Workbook
Name Canopy: '[1]Rough Carpentry'!#REF!
Name Decks: '[1]Rough Carpentry'!#REF!
Name GROSS: [2]Preliminary!$F$17
Name GSF: '[1]Length & Area'!$B$20
Name Location: '[1]Project Information'!$B$5
Name Project: '[1]Project Information'!$B$4
Name Subtotal: '[3]STEP 1 - PROJECT DATA'!$B$7
Name Subtotal: 'STEP 1 - PROJECT DATA'!$B$7
Name Surcharge_Warranty: '[3]STEP 1 - PROJECT DATA'!$B$14
Name Surcharge_Warranty: 'STEP 1 - PROJECT DATA'!$B$14
Name ToiletAccessories: '[1]Interior Takeoff'!#REF!
Name Units: '[1]Unit Counts'!$J$35
Name Units2: [2]Preliminary!$I$20
Name WORK_ITEM: #REF!

Sheet TODO
A1: instructions - include locking and unlocking
A2: logo, branding and colors
A3: Put on FP Hub and get rid of everything else - FP Hub and Shared Drive
A11: STEP 1 - PROJECT DATA
A18: STEP 2 - GCs
A23: STEP 3 - SITE OPS
A29: STEP 4 - ESTIMATE

Sheet US_Holidays__2025_2034_
B1: Year | C1: Holiday | D1: Date
A2: 0 | B2: 2025 | C2: New Year's Day | D2: 45658
A3: 1 | B3: 2025 | C3: Memorial Day | D3: 45803
A4: 2 | B4: 2025 | C4: Independence Day | D4: 45842
A5: 3 | B5: 2025 | C5: Labor Day | D5: 45901
A6: 4 | B6: 2025 | C6: Thanksgiving | D6: 45988
A7: 5 | B7: 2025 | C7: Day After Thanksgiving | D7: 45989
A8: 6 | B8: 2025 | C8: Christmas | D8: 46016
A9: 7 | B9: 2026 | C9: New Year's Day | D9: 46023
A10: 8 | B10: 2026 | C10: Memorial Day | D10: 46167
A11: 9 | B11: 2026 | C11: Independence Day | D11: 46209
A12: 10 | B12: 2026 | C12: Labor Day | D12: 46272
A13: 11 | B13: 2026 | C13: Thanksgiving | D13: 46352
... A71: 69 | B71: 2034 | C71: Christmas | D71: 49303

Sheet COVER
C2: ='STEP 1 - PROJECT DATA'!D6& "." & 'STEP 1 - PROJECT DATA'!D7 -> E26-123.0 | I2: ='STEP 4 - ESTIMATE'!I2 -> Bid Due Date | J2: ='STEP 4 - ESTIMATE'!K2 -> 46010
C3: ='STEP 1 - PROJECT DATA'!C5 -> Project Name | D3: ='STEP 1 - PROJECT DATA'!D5 -> Name | H3: ='STEP 1 - PROJECT DATA'!C10 -> Expected Start | J3: ='STEP 4 - ESTIMATE'!K3 -> 46174
C4: Location | D4: ='STEP 1 - PROJECT DATA'!D8 -> 1234 Main St | H4: ='STEP 1 - PROJECT DATA'!C11 -> Expected Finish | J4: ='STEP 4 - ESTIMATE'!K4 -> 46235
D5: ='STEP 1 - PROJECT DATA'!D9 -> Minneapolis, MN | H5: Duration | J5: ='STEP 1 - PROJECT DATA'!D28 -> 2
C6: ='STEP 1 - PROJECT DATA'!C13 -> Architect | D6: ='STEP 1 - PROJECT DATA'!D13 -> TBD
C7: ='STEP 1 - PROJECT DATA'!C14 -> Plan Set | D7: ='STEP 1 - PROJECT DATA'!D14 -> TBD
C29: ='STEP 1 - PROJECT DATA'!D5 -> Name
C31: ='STEP 1 - PROJECT DATA'!D8 -> 1234 Main St
C33: ='STEP 1 - PROJECT DATA'!D9 -> Minneapolis, MN
C40: ='STEP 1 - PROJECT DATA'!G5 -> 0
C42: ='STEP 1 - PROJECT DATA'!G6 -> 0
E71: Estimator Information
E73: ='STEP 1 - PROJECT DATA'!C18 -> Prepared by | G73: ='STEP 1 - PROJECT DATA'!D18 -> 0
E74: ='STEP 1 - PROJECT DATA'!C19 -> Phone Number | G74: ='STEP 1 - PROJECT DATA'!D19
E75: ='STEP 1 - PROJECT DATA'!C20 -> Email Address | G75: ='STEP 1 - PROJECT DATA'!D20
E76: ='STEP 1 - PROJECT DATA'!C21 -> FP Office | G76: ='STEP 1 - PROJECT DATA'!D21 -> 10050 Crosstown Cir
E77: ='STEP 1 - PROJECT DATA'!C22 -> City, State, Zip | G77: ='STEP 1 - PROJECT DATA'!D22 -> Eden Prairie, MN 55344

Sheet STEP 1 - PROJECT DATA
J3: Estimator Information | K3: Phone Number | L3: Email Address
C4: Project Information | F4: Client Information | J4: Ben Urness | K4: 651 421-1392 | L4: burness@fpcinc.com
C5: Project Name | D5: Name | F5: Client | J5: Cal Pesola | K5: 612 751-4518 | L5: cpesola@fpcinc.com
C6: Estimate # | D6: E26-123 | F6: Contact Person | J6: Calvin Hayes | K6: 612 202-1934 | L6: chayes@fpcinc.com
C7: Revision # | D7: 0 | F7: Phone Number | J7: David Cook | K7: 612 718-9092 | L7: dcook@fpcinc.com
C8: Address | D8: 1234 Main St | F8: Email Address | J8: Haley Kasper | K8: 715 292-4851 | L8: hkasper@fpcinc.com
C9: City, State, Zip | D9: Minneapolis, MN | F9: Bid Due Date | G9: 46010 | J9: Isaac Freitag | K9: 612 545-7352 | L9: ifreitag@fpcinc.com
C10: Expected Start | D10: 46174 | J10: Jared Houle | K10: 651 324-7041 | L10: jhoule@fpcinc.com
C11: Expected Finish | D11: 46235 | J11: Justin Gunderson | K11: 612 366-9181 | L11: jgunderson@fpcinc.com
C12: Project Size | D12: 10 | J12: Kevin Swanson | K12: 612 817-6835 | L12: kswanson@fpcinc.com
C13: Architect | D13: TBD | J13: Spencer Will | K13: 952 818-4711 | L13: swill@fpcinc.com
C14: Plan Set | D14: TBD
J15: Target Profit Percentages
C17: Estimator Information | F17: Contingency, Fee, Insurances | J17: Project Size (Low) | K17: Project Size (High) | L17: Profit %
C18: Prepared by | F18: Construction Contingency | G18: 0 | J18: 0 | K18: 10000 | L18: 0.17
C19: Phone Number | D19: =_xlfn.XLOOKUP(D18,$J$4:$J$12,$K$4:$K$12,"") | F19: Design Contingency | G19: 0 | J19: 10000 | K19: 100000 | L19: 0.12
C20: Email Address | D20: =_xlfn.XLOOKUP(D18,$J$4:$J$12,$L$4:$L$12,"") | F20: Builders Risk Insurance | G20: 0 | J20: 100000 | K20: 250000 | L20: 0.09
C21: FP Office | D21: 10050 Crosstown Cir | F21: Special Insurance | G21: 0 | J21: 250000 | K21: 500000 | L21: 0.08
C22: City, State, Zip | D22: Eden Prairie, MN 55344 | F22: General Liability Insurance | G22: 0.01 | J22: 500000 | K22: 2000000 | L22: 0.07
F23: Bond | G23: 0 | J23: 2000000 | K23: 3000000 | L23: 0.06
F24: Fee | G24: 0.05 | J24: 3000000 | K24: 5000000 | L24: 0.05
J25: 5000000 | K25: 8000000 | L25: 0.04
C27: Project Duration | F27: Project Type and Sector | J27: Project Type | K27: Description
C28: Months | D28: =YEARFRAC(D10, D11) * 12 -> 2 | F28: Project Type | J28: Adaptive Reuse | K28: Repurposing existing buildings for new uses.
C29: Weeks | D29: =(D11 - D10) / 7 -> 8.7142857 | F29: Market Sector | J29: Ground-Up (New Construction) | K29: New builds from scratch.
C30: Total Calendar Days | D30: =D11-D10 -> 61 | J30: Renovation / Remodel | K30: Updates or overhauls to existing structures.
C31: Working Days | D31: =NETWORKDAYS(D10, D11, US_Holidays__2025_2034_!D2:D71) -> 44 | J31: Office Tenant Improvement (TI) | K31: Interior buildouts for new or existing office tenants.
J32: Site Development | K32: Prepping land for future construction.
C34: Building Permit Calculation | J34: Market Sector | K34: Description
J35: Commercial | K35: Retail, Grocery Store, Auto, Banks
C36: $1.00 - $500.00 | D36: =IF('STEP 2 - GCs'!H35 <501, 'STEP 2 - GCs'!H35, 0) -> 0 | E36: =IF(D36>0,36.7,0) -> 0 | J36: Restaurant | K36: Quick Service Restaurant (QSR), Fast Casual, Casual Dining, Fine Dining, Food Hall, Coffee Shop
C37: $501.00 - $2,000.00 | D37: =IF(AND(501 <'STEP 2 - GCs'!H35,'STEP 2 - GCs'!H35 < 2001), 'STEP 2 - GCs'!H35, 0) -> 0 | E37: =IF(D37>0,SUM((D37-500)*0.045)+36.7,0) -> 0 | J37: Healthcare | K37: Medical Clinics, Dental Offices, Animal Health/Vet Clinics
C38: $2,001.00 - $25,000.00 | D38: =IF(AND(2001 <'STEP 2 - GCs'!H35,'STEP 2 - GCs'!H35 < 25001), 'STEP 2 - GCs'!H35, 0) -> 0 | E38: =IF(D38>0,SUM((D38-2000)*0.0206)+104.2,0) -> 0 | J38: Housing and Hotel | K38: Multi-family, Senior Living, Single Family Homes, Hotels
C39: $25,001.00 - $50,000.00 | D39: =IF(AND(25001 <'STEP 2 - GCs'!H35,'STEP 2 - GCs'!H35 < 50001), 'STEP 2 - GCs'!H35, 0) -> 0 | E39: =IF(D39>0,SUM((D39-25000)*0.0149)+578,0) -> 0 | J39: Industrial | K39: Manufacturing, Warehouses, Cold Storage, Self-Storage
C40: $50,001.00 - $100,000.00 | D40: =IF(AND(50001 <'STEP 2 - GCs'!H35,'STEP 2 - GCs'!H35 < 100001), 'STEP 2 - GCs'!H35, 0) -> 0 | E40: =IF(D40>0,SUM((D40-50000)*0.0106)+950.5,0) -> 0 | J40: Government | K40: City Buildings, Courthouses, Post Offices
C41: $100,001.00 - $500,000.00 | D41: =IF(AND(100001 <'STEP 2 - GCs'!H35,'STEP 2 - GCs'!H35 < 500001), 'STEP 2 - GCs'!H35, 0) -> 117389 | E41: =IF(D41>0,SUM(((D41-100000)*0.0084)+1480.5),0) -> 1626.5676 | J41: Educational | K41: Schools, Colleges, Universities, Daycare
C42: $500,001.00 - $1,000,000.00 | D42: =IF(AND(500001 <'STEP 2 - GCs'!H35,'STEP 2 - GCs'!H35 < 1000001), 'STEP 2 - GCs'!H35, 0) -> 0 | E42: =IF(D42>0,SUM((D42-500000)*0.0069)+4840.5,0) -> 0 | J42: Workplace | K42: Office Buildings (Traditional, Open, Hybrid, Coworking)
C43: $1,000,001.00 and Up | D43: =IF('STEP 2 - GCs'!H35 > 1000001, 'STEP 2 - GCs'!H35, 0) -> 0 | E43: =IF(D43>0,SUM((D43-1000000)*0.0056)+8290.5,0) -> 0
C44: Building Permit Fee | F44: =SUM(E36:E43) -> 1626.5676
C45: Plan Review Fee | F45: =SUM(F44)*0.65 -> 1057.2689
...

Sheet STEP 2 - GCs
M1: Low Risk
C2: ='STEP 1 - PROJECT DATA'!D6& "." & 'STEP 1 - PROJECT DATA'!D7 -> E26-123.0 | I2: ='STEP 4 - ESTIMATE'!I2 -> Bid Due Date | J2: ='STEP 4 - ESTIMATE'!K2 -> 46010 | M2: Medium Risk
C3: ='STEP 1 - PROJECT DATA'!C5 -> Project Name | D3: ='STEP 1 - PROJECT DATA'!D5 -> Name | E3: Supervision & General Conditions | H3: ='STEP 1 - PROJECT DATA'!C10 -> Expected Start | J3: ='STEP 4 - ESTIMATE'!K3 -> 46174 | M3: High Risk
C4: Location | D4: ='STEP 1 - PROJECT DATA'!D8 -> 1234 Main St | H4: ='STEP 1 - PROJECT DATA'!C11 -> Expected Finish | J4: ='STEP 4 - ESTIMATE'!K4 -> 46235
D5: ='STEP 1 - PROJECT DATA'!D9 -> Minneapolis, MN | H5: Duration | J5: ='STEP 1 - PROJECT DATA'!D28 -> 2
C6: ='STEP 1 - PROJECT DATA'!C13 -> Architect | D6: ='STEP 1 - PROJECT DATA'!D13 -> TBD
C7: ='STEP 1 - PROJECT DATA'!C14 -> Plan Set | D7: ='STEP 1 - PROJECT DATA'!D14 -> TBD | J7: Bldg. Sqft.
J8: ='STEP 1 - PROJECT DATA'!D12 -> 10
C9: Code | D9: Description | E9: Utilization | F9: Quantity | G9: Unit | H9: Rate | I9: Total | J9: Cost/S.F.
C10: DIVISION 01 — SUPERVISION | D10: GENERAL CONDITIONS
C12: 01-0410 | D12: Sr Superintendent | E12: 1 | F12: =$J$5*4.33*E12*40 -> 346.4 | G12: hr | H12: 125 | I12: =F12*H12 -> 43300 | J12: =IF($J$8=0, 0, I12/$J$8) -> 4330
C13: 01-0420 | D13: Superintendent | E13: 0 | F13: =$J$5*4.33*E13*40 -> 0 | G13: hr | H13: 110 | I13: =F13*H13 -> 0 | J13: =IF($J$8=0, 0, I13/$J$8) -> 0
C14: 01-0430 | D14: Asst. Superintendent | E14: 0 | F14: =$J$5*4.33*E14*40 -> 0 | G14: hr | H14: 85 | I14: =F14*H14 -> 0 | J14: =IF($J$8=0, 0, I14/$J$8) -> 0
H16: Total Supervision | I16: =SUM(I11:I15) -> 43300 | J16: =IF($J$8=0, 0, I16/$J$8) -> 4330
C17: DIVISION 01 — DESIGN | D17: GENERAL CONDITIONS | E17: =SUM(I18:I24) -> 0
C19: 01-0001 | D19: Preconstruction Fees | F19: 0 | G19: ls | H19: 0 | I19: =F19*H19 -> 0 | J19: =IF($J$8=0, 0, I19/$J$8) -> 0
C20: 01-0130 | D20: Design - Architecture | F20: 0 | G20: ls | H20: 0 | I20: =F20*H20 -> 0 | J20: =IF($J$8=0, 0, I20/$J$8) -> 0
C21: 01-0160 | D21: Design - Civil | F21: 0 | G21: ls | H21: 0 | I21: =F21*H21 -> 0 | J21: =IF($J$8=0, 0, I21/$J$8) -> 0
C22: 01-0180 | D22: Design - MEP | F22: 0 | G22: ls | H22: 0 | I22: =F22*H22 -> 0 | J22: =IF($J$8=0, 0, I22/$J$8) -> 0
C23: 01-0210 | D23: Design - Structural | F23: 0 | G23: ls | H23: 0 | I23: =F23*H23 -> 0 | J23: =IF($J$8=0, 0, I23/$J$8) -> 0
C25: DIVISION 01 — PROJECT MANAGEMENT | D25: GENERAL CONDITIONS | E25: =SUM(I26:I32) -> 23382 | L25: =E25/'STEP 4 - ESTIMATE'!$I$341 -> 0.19918473 | M25: Min 2%
C27: 01-0310 | D27: Project Executive | E27: 0 | F27: =$J$5*4.33*E27*40 -> 0 | G27: hr | H27: 175 | I27: =F27*H27 -> 0 | J27: =IF($J$8=0, 0, I27/$J$8) -> 0
C28: 01-0320 | D28: Sr Project Manager | E28: 0.5 | F28: =$J$5*4.33*E28*40 -> 173.2 | G28: hr | H28: 135 | I28: =F28*H28 -> 23382 | J28: =IF($J$8=0, 0, I28/$J$8) -> 2338.2
C29: 01-0330 | D29: Project Manager | E29: 0 | F29: =$J$5*4.33*E29*40 -> 0 | G29: hr | H29: 120 | I29: =F29*H29 -> 0 | J29: =IF($J$8=0, 0, I29/$J$8) -> 0
C30: 01-0340 | D30: Project Engineer | E30: 0 | F30: =$J$5*4.33*E30*40 -> 0 | G30: hr | H30: 85 | I30: =F30*H30 -> 0 | J30: =IF($J$8=0, 0, I30/$J$8) -> 0
C31: 01-0510 | D31: Project Assistant | E31: 0 | F31: =$J$5*4.33*E31*40 -> 0 | G31: hr | H31: 55 | I31: =F31*H31 -> 0 | J31: =IF($J$8=0, 0, I31/$J$8) -> 0
C33: DIVISION 01 — GENERAL CONDITIONS | D33: GENERAL CONDITIONS | E33: =SUM(I34:I57) -> 41316.85
C35: 01-0610 | D35: Safety Consultant | E35: REQUIRED | F35: 0.0002 | G35: % | H35: 117389 | I35: =F35*H35 -> 23.4778 | J35: =IF($J$8=0, 0, I35/$J$8) -> 2.34778 | L35: ='STEP 4 - ESTIMATE'!$I$341 -> 117388.51 | M35: Enter this amount in column H when estimate complete
C36: 01-1000 | D36: Small Tools | F36: =$J$5 -> 2 | G36: mo | H36: 500 | I36: =F36*H36 -> 1000 | J36: =IF($J$8=0, 0, I36/$J$8) -> 100
C37: 01-1200 | D37: Fuel and Vehicle Charges | E37: 1 | F37: =$J$5*E37 -> 2 | G37: mo | H37: 1200 | I37: =F37*H37 -> 2400 | J37: =IF($J$8=0, 0, I37/$J$8) -> 240
C38: 01-1400 | D38: Travel and Meals | F38: 0 | G38: mo | H38: 0 | I38: =F38*H38 -> 0 | J38: =IF($J$8=0, 0, I38/$J$8) -> 0
C39: 01-1600 | D39: Procore | E39: REQUIRED | F39: 0.0019 | G39: % | H39: =H35 -> 117389 | I39: =F39*H39 -> 223.0391 | J39: =IF($J$8=0, 0, I39/$J$8) -> 22.30391 | L39: Copies cell from H35
C40: 01-4010 | D40: Quality | F40: =$J$5 -> 2 | G40: mo | H40: 500 | I40: =F40*H40 -> 1000 | J40: =IF($J$8=0, 0, I40/$J$8) -> 100
C41: 01-5110 | D41: Temp Office Set up and Takedown | F41: 1 | G41: ea | H41: 9000 | I41: =F41*H41 -> 9000 | J41: =IF($J$8=0, 0, I41/$J$8) -> 900
C42: 01-5110 | D42: Temp Office | F42: =$J$5 -> 2 | G42: mo | H42: 850 | I42: =F42*H42 -> 1700 | J42: =IF($J$8=0, 0, I42/$J$8) -> 170
C43: 01-5111 | D43: Cell Phone | E43: REQUIRED | F43: =$J$5 -> 2 | G43: mo | H43: 135 | I43: =F43*H43 -> 270 | J43: =IF($J$8=0, 0, I43/$J$8) -> 27
C44: 01-5112 | D44: Jobsite Office Equipment | F44: =$J$5 -> 2 | G44: mo | H44: 250 | I44: =F44*H44 -> 500 | J44: =IF($J$8=0, 0, I44/$J$8) -> 50
C45: 01-5114 | D45: Project Computers / Internet | F45: =$J$5 -> 2 | G45: mo | H45: 300 | I45: =F45*H45 -> 600 | J45: =IF($J$8=0, 0, I45/$J$8) -> 60
C46: 01-5120 | D46: Storage Trailer | F46: =$J$5 -> 2 | G46: mo | H46: 800 | I46: =F46*H46 -> 1600 | J46: =IF($J$8=0, 0, I46/$J$8) -> 160
C47: 01-5130 | D47: Dumpsters | F47: =$J$5*4 -> 8 | G47: ea | H47: 650 | I47: =F47*H47 -> 5200 | J47: =IF($J$8=0, 0, I47/$J$8) -> 520
...

Sheet STEP 3 - SITE OPS
C2: ='STEP 2 - GCs'!C2 -> E26-123.0 | I2: ='STEP 4 - ESTIMATE'!I2 -> Bid Due Date | J2: ='STEP 4 - ESTIMATE'!K2 -> 46010 | M2: Low Risk
C3: ='STEP 2 - GCs'!C3 -> Project Name | D3: ='STEP 2 - GCs'!D3 -> Name | E3: Site Operations | H3: ='STEP 1 - PROJECT DATA'!C10 -> Expected Start | J3: ='STEP 4 - ESTIMATE'!K3 -> 46174 | M3: Medium Risk
C4: ='STEP 2 - GCs'!C4 -> Location | D4: ='STEP 2 - GCs'!D4 -> 1234 Main St | H4: ='STEP 1 - PROJECT DATA'!C11 -> Expected Finish | J4: ='STEP 4 - ESTIMATE'!K4 -> 46235 | M4: High Risk
D5: ='STEP 2 - GCs'!D5 -> Minneapolis, MN | H5: Duration | J5: ='STEP 1 - PROJECT DATA'!D28 -> 2
C6: ='STEP 2 - GCs'!C6 -> Architect | D6: ='STEP 2 - GCs'!D6 -> TBD
C7: ='STEP 2 - GCs'!C7 -> Plan Set | D7: ='STEP 2 - GCs'!D7 -> TBD | J7: Bldg. Sqft.
J8: ='STEP 4 - ESTIMATE'!K8 -> 10
C9: Code | D9: Description | F9: Quantity | G9: Unit | H9: Rate | I9: Total | J9: Cost/S.F.
C10: 02-0000 — SITE OPERATIONS | D10: GENERAL CONDITIONS | E10: =SUM(I11:I28) -> 2.5
C12: 02-3200 | D12: Soil Borings | F12: 0 | G12: ls | H12: 0 | I12: =F12*H12 -> 0 | J12: =IF($J$8=0, 0, I12/$J$8) -> 0
C13: 02-5100 | D13: FFE Relocation | F13: 0 | G13: ls | H13: 0 | I13: =F13*H13 -> 0 | J13: =IF($J$8=0, 0, I13/$J$8) -> 0
C14: 02-8213 | D14: Abatement | F14: 0 | G14: ls | H14: 0 | I14: =F14*H14 -> 0 | J14: =IF($J$8=0, 0, I14/$J$8) -> 0
C15: 02-9010 | D15: Progress Cleaning - Payroll | E15: 0 | F15: =$J$5*4.33*E15*40 -> 0 | G15: hr | H15: 74 | I15: =F15*H15 -> 0 | J15: =IF($J$8=0, 0, I15/$J$8) -> 0
C16: 02-9010 | D16: Progress Cleaning - Hired | E16: 0 | F16: =$J$5*4.33*E16*40 -> 0 | G16: hr | H16: 54 | I16: =F16*H16 -> 0 | J16: =IF($J$8=0, 0, I16/$J$8) -> 0
C17: 02-9015 | D17: Safety | F17: 0 | G17: mo | H17: 500 | I17: =F17*H17 -> 0 | J17: =IF($J$8=0, 0, I17/$J$8) -> 0
C18: 02-9020 | D18: Temp Protection | F18: =J8 -> 10 | G18: sf | H18: 0.25 | I18: =F18*H18 -> 2.5 | J18: =IF($J$8=0, 0, I18/$J$8) -> 0.25
C19: 02-9025 | D19: Temporary Partitions | F19: 0 | G19: ea | H19: 5000 | I19: =F19*H19 -> 0 | J19: =IF($J$8=0, 0, I19/$J$8) -> 0
C20: 02-9030 | D20: Traffic Control and Jersey Barriers | F20: 0 | G20: lf | H20: 25 | I20: =F20*H20 -> 0 | J20: =IF($J$8=0, 0, I20/$J$8) -> 0
C21: 02-9035 | D21: Temporary Fencing | F21: 0 | G21: lf | H21: 15 | I21: =F21*H21 -> 0 | J21: =IF($J$8=0, 0, I21/$J$8) -> 0
C22: 02-9040 | D22: Scrim | F22: 0 | G22: lf | H22: 20 | I22: =F22*H22 -> 0 | J22: =IF($J$8=0, 0, I22/$J$8) -> 0
C23: 02-9045 | D23: Temp Access Roads | F23: 0 | G23: ls | H23: 5000 | I23: =F23*H23 -> 0 | J23: =IF($J$8=0, 0, I23/$J$8) -> 0
C24: 02-9050 | D24: Site Security | F24: 0 | G24: mo | H24: 2000 | I24: =F24*H24 -> 0 | J24: =IF($J$8=0, 0, I24/$J$8) -> 0
C25: 02-9055 | D25: Site Security Cameras | F25: 0 | G25: mo | H25: 1000 | I25: =F25*H25 -> 0 | J25: =IF($J$8=0, 0, I25/$J$8) -> 0
C26: 02-9060 | D26: Jobsite Camera | F26: 0 | G26: mo | H26: 1000 | I26: =F26*H26 -> 0 | J26: =IF($J$8=0, 0, I26/$J$8) -> 0
C27: 02-9065 | D27: Construction Permits (not building permit) | F27: 0 | G27: ea | H27: 0 | I27: =F27*H27 -> 0 | J27: =IF($J$8=0, 0, I27/$J$8) -> 0
H29: Total Site Operations | I29: =SUM(I11:I28) -> 2.5 | J29: =IF($J$8=0, 0, I29/$J$8) -> 0.25
C30: 02-4100 — DEMOLITION | D30: GENERAL CONDITIONS | E30: =SUM(I31:I34) -> 0
C32: 02-4100 | D32: Demolition | F32: 0 | G32: sf | H32: 6 | I32: =F32*H32 -> 0 | J32: =IF($J$8=0, 0, I32/$J$8) -> 0
C33: 02-4100 | D33: Demolition - Sawcutting | F33: 0 | G33: ls | H33: 0 | I33: =F33*H33 -> 0 | J33: =IF($J$8=0, 0, I33/$J$8) -> 0
H35: Total Demolition | I35: =SUM(I31:I34) -> 0 | J35: =IF($J$8=0, 0, I35/$J$8) -> 0
C36: 02-9005 — FINAL CLEANING | D36: GENERAL CONDITIONS | E36: =SUM(I37:I39) -> 0
C38: 02-9005 | D38: Final Cleaning | F38: 0 | G38: ea | H38: 2500 | I38: =F38*H38 -> 0 | J38: =IF($J$8=0, 0, I38/$J$8) -> 0
H40: Total Final Cleaning | I40: =SUM(I37:I39) -> 0 | J40: =IF($J$8=0, 0, I40/$J$8) -> 0
C41: 02-9070 — SWPPP PERMIT | D41: GENERAL CONDITIONS | E41: =SUM(I42:I44) -> 0
C43: 02-9070 | D43: SWPPP Permit | F43: 0 | G43: ea | H43: 400 | I43: =F43*H43 -> 0 | J43: =IF($J$8=0, 0, I43/$J$8) -> 0
H45: Total SWPPP Permit | I45: =SUM(I42:I44) -> 0 | J45: =IF($J$8=0, 0, I45/$J$8) -> 0
C46: 02-9200 — SURVEY & LAYOUT | D46: GENERAL CONDITIONS | E46: =SUM(I47:I50) -> 0
C48: 02-9200 | D48: Survey & Layout | F48: 0 | G48: ls | H48: 0 | I48: =F48*H48 -> 0 | J48: =IF($J$8=0, 0, I48/$J$8) -> 0
C49: 02-9200 | D49: Survey & Layout - Floor Scanning | F49: 0 | G49: ls | H49: 0 | I49: =F49*H49 -> 0 | J49: =IF($J$8=0, 0, I49/$J$8) -> 0
H51: Total Survey and Layout | I51: =SUM(I47:I50) -> 0 | J51: =IF($J$8=0, 0, I51/$J$8) -> 0
...

Sheet STEP 4 - ESTIMATE
C2: ='STEP 1 - PROJECT DATA'!D6& "." & 'STEP 1 - PROJECT DATA'!D7 -> E26-123.0 | I2: ='STEP 1 - PROJECT DATA'!F9 -> Bid Due Date | K2: ='STEP 1 - PROJECT DATA'!G9 -> 46010 | O2: Low Risk
C3: ='STEP 1 - PROJECT DATA'!C5 -> Project Name | D3: ='STEP 1 - PROJECT DATA'!D5 -> Name | E3: Detailed Estimate | H3: ='STEP 1 - PROJECT DATA'!C10 -> Expected Start | K3: ='STEP 1 - PROJECT DATA'!D10 -> 46174 | O3: Medium Risk
C4: Location | D4: ='STEP 1 - PROJECT DATA'!D8 -> 1234 Main St | H4: ='STEP 1 - PROJECT DATA'!C11 -> Expected Finish | K4: ='STEP 1 - PROJECT DATA'!D11 -> 46235 | O4: High Risk
D5: ='STEP 1 - PROJECT DATA'!D9 -> Minneapolis, MN | H5: Duration | K5: ='STEP 1 - PROJECT DATA'!D28 -> 2
C6: ='STEP 1 - PROJECT DATA'!C13 -> Architect | D6: ='STEP 1 - PROJECT DATA'!D13 -> TBD
C7: ='STEP 1 - PROJECT DATA'!C14 -> Plan Set | D7: ='STEP 1 - PROJECT DATA'!D14 -> TBD | J7: ='STEP 1 - PROJECT DATA'!C58 -> # of Units | K7: ='STEP 1 - PROJECT DATA'!C12 -> Project Size
J8: ='STEP 1 - PROJECT DATA'!D58 -> 100 | K8: ='STEP 1 - PROJECT DATA'!D12 -> 10
A9: TYPE | C9: Code | D9: Description | F9: Quantity | G9: Unit | H9: Unit Price | I9: Total | J9: Cost/Unit | K9: Cost/S.F. | O9: Vendor | P9: Actual
A10: TI | C10: DIVISION 01 — GENERAL CONDITIONS | D10: GENERAL CONDITIONS | E10: =SUM(I11:I14) -> 107998.85
A11: TI
A12: TI | C12: 01-0000.001 | D12: General Conditions | F12: 1 | G12: ls | H12: ='STEP 2 - GCs'!I58 -> 64698.85 | I12: =IF(ISNUMBER(F12), F12 * H12, 0) -> 64698.85 | J12: =IF($J$8=0, 0, I12/$J$8) -> 646.9885 | K12: =IF($K$8=0, 0, I12/$K$8) -> 6469.885 | O12: Fendler Patterson | P12: =I12 -> 64698.85 | S12: ='STEP 2 - GCs'!I58='STEP 4 - ESTIMATE'!I12 -> TRUE
A13: TI | C13: 01-0400.002 | D13: Supervision | F13: 1 | G13: ls | H13: ='STEP 2 - GCs'!I16 -> 43300 | I13: =IF(ISNUMBER(F13), F13 * H13, 0) -> 43300 | J13: =IF($J$8=0, 0, I13/$J$8) -> 433 | K13: =IF($K$8=0, 0, I13/$K$8) -> 4330 | O13: Fendler Patterson | P13: =I13 -> 43300 | S13: =I13='STEP 2 - GCs'!I16 -> TRUE
A14: TI
A15: TI | C15: DIVISION 02 — SITE OPERATIONS | D15: SITE OPERATIONS | E15: =SUM(I16:I25) -> 2.5
A16: TI
A17: TI | C17: 02-0000.001 | D17: Site Operations | F17: 1 | G17: ls | H17: ='STEP 3 - SITE OPS'!I29 -> 2.5 | I17: =IF(ISNUMBER(F17), F17 * H17, 0) -> 2.5 | J17: =IF($J$8=0, 0, I17/$J$8) -> 0.025 | K17: =IF($K$8=0, 0, I17/$K$8) -> 0.25 | S17: =I17='STEP 3 - SITE OPS'!I29 -> TRUE
A18: TI | C18: 02-4100.002 | D18: Demolition | F18: 1 | G18: ls | H18: ='STEP 3 - SITE OPS'!I35 -> 0 | I18: =IF(ISNUMBER(F18), F18 * H18, 0) -> 0 | J18: =IF($J$8=0, 0, I18/$J$8) -> 0 | K18: =IF($K$8=0, 0, I18/$K$8) -> 0 | S18: =I18='STEP 3 - SITE OPS'!I35 -> TRUE
A19: TI | C19: 02-9005.003 | D19: Final Cleaning | F19: 1 | G19: ls | H19: ='STEP 3 - SITE OPS'!I38 -> 0 | I19: =IF(ISNUMBER(F19), F19 * H19, 0) -> 0 | J19: =IF($J$8=0, 0, I19/$J$8) -> 0 | K19: =IF($K$8=0, 0, I19/$K$8) -> 0 | S19: ='STEP 4 - ESTIMATE'!I19='STEP 3 - SITE OPS'!I40 -> TRUE
C20: 02-9070.004 | D20: SWPPP Permit | F20: 1 | G20: ls | H20: ='STEP 3 - SITE OPS'!I43 -> 0 | I20: =IF(ISNUMBER(F20), F20 * H20, 0) -> 0 | J20: =IF($J$8=0, 0, I20/$J$8) -> 0 | K20: =IF($K$8=0, 0, I20/$K$8) -> 0 | S20: =I20='STEP 3 - SITE OPS'!I45 -> TRUE
C21: 02-9200.005 | D21: Survey and Layout | F21: 1 | G21: ls | H21: ='STEP 3 - SITE OPS'!I51 -> 0 | I21: =IF(ISNUMBER(F21), F21 * H21, 0) -> 0 | J21: =IF($J$8=0, 0, I21/$J$8) -> 0 | K21: =IF($K$8=0, 0, I21/$K$8) -> 0 | S21: ='STEP 4 - ESTIMATE'!I21='STEP 3 - SITE OPS'!I51 -> TRUE
C22: 02-9300.006 | D22: Building and Site Services | F22: 1 | G22: ls | H22: ='STEP 3 - SITE OPS'!I62 -> 0 | I22: =IF(ISNUMBER(F22), F22 * H22, 0) -> 0 | J22: =IF($J$8=0, 0, I22/$J$8) -> 0 | K22: =IF($K$8=0, 0, I22/$K$8) -> 0 | S22: =I22='STEP 3 - SITE OPS'!I62 -> TRUE
A23: TI | C23: 02-9400.007 | D23: Site Equipment | F23: 1 | G23: ls | H23: ='STEP 3 - SITE OPS'!I72 -> 0 | I23: =IF(ISNUMBER(F23), F23 * H23, 0) -> 0 | J23: =IF($J$8=0, 0, I23/$J$8) -> 0 | K23: =IF($K$8=0, 0, I23/$K$8) -> 0 | S23: =I23='STEP 3 - SITE OPS'!I72 -> TRUE
C24: 02-9500.008 | D24: Special Inspections | F24: 1 | G24: ls | H24: ='STEP 3 - SITE OPS'!I81 -> 0 | I24: =IF(ISNUMBER(F24), F24 * H24, 0) -> 0 | J24: =IF($J$8=0, 0, I24/$J$8) -> 0 | K24: =IF($K$8=0, 0, I24/$K$8) -> 0 | S24: =I24='STEP 3 - SITE OPS'!I82 -> TRUE
A25: TI
A26: TI | C26: DIVISION 03 — CONCRETE | D26: CONCRETE | E26: =SUM(I27:I52) -> 0
A27: TI
D28: CONCRETE
C29: 03-0000.001 | D29: Cast In-Place Concrete | F29: 0 | G29: ls | H29: 1 | I29: =IF(ISNUMBER(F29), F29 * H29, 0) -> 0 | J29: =IF($J$8=0, 0, I29/$J$8) -> 0 | K29: =IF($K$8=0, 0, I29/$K$8) -> 0
C30: 03-0000.002 | D30: Footings | F30: 0 | G30: cy | H30: 575 | I30: =IF(ISNUMBER(F30), F30 * H30, 0) -> 0 | J30: =IF($J$8=0, 0, I30/$J$8) -> 0 | K30: =IF($K$8=0, 0, I30/$K$8) -> 0
C31: 03-0000.003 | D31: Concrete Strip Footing | F31: 0 | G31: lf | H31: 55 | I31: =IF(ISNUMBER(F31), F31 * H31, 0) -> 0 | J31: =IF($J$8=0, 0, I31/$J$8) -> 0 | K31: =IF($K$8=0, 0, I31/$K$8) -> 0
C32: 03-0000.004 | D32: Concrete Fnd Pads | F32: 0 | G32: ea | H32: 4000 | I32: =IF(ISNUMBER(F32), F32 * H32, 0) -> 0 | J32: =IF($J$8=0, 0, I32/$J$8) -> 0 | K32: =IF($K$8=0, 0, I32/$K$8) -> 0
C33: 03-0000.005 | D33: Concrete Walls | F33: 0 | G33: sf | H33: 33 | I33: =IF(ISNUMBER(F33), F33 * H33, 0) -> 0 | J33: =IF($J$8=0, 0, I33/$J$8) -> 0 | K33: =IF($K$8=0, 0, I33/$K$8) -> 0
C34: 03-0000.006 | D34: Concrete Columns | F34: 0 | G34: ea | H34: 1000 | I34: =IF(ISNUMBER(F34), F34 * H34, 0) -> 0 | J34: =IF($J$8=0, 0, I34/$J$8) -> 0 | K34: =IF($K$8=0, 0, I34/$K$8) -> 0
C35: 03-0000.007 | D35: SOG | F35: 0 | G35: sf | H35: 7 | I35: =IF(ISNUMBER(F35), F35 * H35, 0) -> 0 | J35: =IF($J$8=0, 0, I35/$J$8) -> 0 | K35: =IF($K$8=0, 0, I35/$K$8) -> 0
C36: 03-0000.008 | D36: Under-Slab Insulation | F36: 0 | G36: sf | H36: 2 | I36: =IF(ISNUMBER(F36), F36 * H36, 0) -> 0 | J36: =IF($J$8=0, 0, I36/$J$8) -> 0 | K36: =IF($K$8=0, 0, I36/$K$8) -> 0
C37: 03-0000.009 | D37: Topping Slab on Precast Parking | F37: 0 | G37: sf | H37: 6 | I37: =IF(ISNUMBER(F37), F37 * H37, 0) -> 0 | J37: =IF($J$8=0, 0, I37/$J$8) -> 0 | K37: =IF($K$8=0, 0, I37/$K$8) -> 0
C38: 03-0000.010 | D38: Amenity Deck Topping Slab and Finished Slab | F38: 0 | G38: sf | H38: 6 | I38: =IF(ISNUMBER(F38), F38 * H38, 0) -> 0 | J38: =IF($J$8=0, 0, I38/$J$8) -> 0 | K38: =IF($K$8=0, 0, I38/$K$8) -> 0
C39: 03-0000.011 | D39: Post Tension Concrete | F39: 0 | G39: cy | H39: 400 | I39: =IF(ISNUMBER(F39), F39 * H39, 0) -> 0 | J39: =IF($J$8=0, 0, I39/$J$8) -> 0 | K39: =IF($K$8=0, 0, I39/$K$8) -> 0
C40: 03-0000.012 | D40: Concrete Patios | F40: 0 | G40: sf | H40: 7 | I40: =IF(ISNUMBER(F40), F40 * H40, 0) -> 0 | J40: =IF($J$8=0, 0, I40/$J$8) -> 0 | K40: =IF($K$8=0, 0, I40/$K$8) -> 0
A42: TI | D42: POLISHED CONCRETE
...

Sheet VEs_ALTS_MF
C2: ='STEP 1 - PROJECT DATA'!D6& "." & 'STEP 1 - PROJECT DATA'!D7 -> E26-123.0
C3: ='STEP 1 - PROJECT DATA'!C5 -> Project Name | D3: ='STEP 1 - PROJECT DATA'!D5 -> Name | E3: Value Engineering / Project Alternates | K3: Date | L3: ='STEP 1 - PROJECT DATA'!G9 -> 46010
C4: Location | D4: ='STEP 1 - PROJECT DATA'!D8 -> 1234 Main St | K4: Pricing Legend
D5: ='STEP 1 - PROJECT DATA'!D9 -> Minneapolis, MN | K5: P | L5: = Preliminary
C6: ='STEP 1 - PROJECT DATA'!C13 -> Architect | D6: ='STEP 1 - PROJECT DATA'!D13 -> TBD | K6: A | L6: = Allowance
C7: ='STEP 1 - PROJECT DATA'!C14 -> Plan Set | D7: ='STEP 1 - PROJECT DATA'!D14 -> TBD | K7: C | L7: = Confirmed
D9: Description | E9: Estimated Cost | F9: Pricing Type | G9: Accepted (In Estimate) | H9: Accepted (Pending Estimate) | I9: Pending | J9: Rejected | K9: Ball-in-Court | L9: Comments
C10: Alternate 01: | D10: GENERAL CONDITIONS | E10: =SUM(E11:E15) -> 2700
C11: 1.1 | D11: Example | E11: 1500 | F11: P | G11: =$E$11 -> 1500 | L11: Notes
C12: 1.2 | D12: 2 | E12: 100 | G12: =$E$12 -> 100
C13: 1.3 | D13: 3 | E13: 500 | G13: =$E$13 -> 500
C14: 1.4 | D14: 4 | E14: 600 | G14: =$E$14 -> 600
C15: 1.5 | E15: 0 | I15: =$E$15 -> 0
C16: Alternate 02: | D16: GENERAL CONDITIONS
C17: =C11+1 -> 2.1 | E17: 0
C18: =C17+0.1 -> 2.2 | E18: 0
C19: =C18+0.1 -> 2.3 | E19: 0
C20: =C19+0.1 -> 2.4 | E20: 0
C21: =C20+0.1 -> 2.5 | E21: 0
C22: Alternate 03: | D22: GENERAL CONDITIONS
C23: =C17+1 -> 3.1 | E23: 0
C24: =C23+0.1 -> 3.2 | E24: 0
C25: =C24+0.1 -> 3.3 | E25: 0
C26: =C25+0.1 -> 3.4 | E26: 0
C27: =C26+0.1 -> 3.5 | E27: 0
C28: Alternate 04: | D28: GENERAL CONDITIONS
C29: =C23+1 -> 4.1 | E29: 0
C30: =C29+0.1 -> 4.2 | E30: 0
C31: =C30+0.1 -> 4.3 | E31: 0
C32: =C31+0.1 -> 4.4 | E32: 0
C33: =C32+0.1 -> 4.5 | E33: 0
C34: DIVISION 05 — METALS | D34: METALS
C35: =C29+1 -> 5.1 | E35: 0
C36: =C35+0.1 -> 5.2 | E36: 0
C37: =C36+0.1 -> 5.3 | E37: 0
C38: =C37+0.1 -> 5.4 | E38: 0
C39: =C38+0.1 -> 5.5 | E39: 0
C40: DIVISION 06 — WOOD, PLASTICS, AND COMPOSITES
C41: =C35+1 -> 6.1 | E41: 0
C42: =C41+0.1 -> 6.2 | E42: 0
...

Sheet VEs_ALTS_COMMERCIAL 
C2: ='STEP 1 - PROJECT DATA'!D6& "." & 'STEP 1 - PROJECT DATA'!D7 -> E26-123.0
D3: Value Engineering / Project Alternates
M4: Alt Markup % | N4: 0.1
D9: Description | E9: Comments | F9: Total | J9: Vendor | K9: Description | L9: Comments | M9: Vendor Cost | N9: Total
A10: =IF(F10<>0,1,0) -> 0 | C10: =J10 -> Alternate 01: | F10: =F15 -> 0 | J10: Alternate 01:
A11: =IF(F11<>0,1,0) -> 0 | D11: =IF(K11=0," ",K11) | F11: =N11 -> 0 | M11: 0 | N11: =M11*1+M11*$N$4 -> 0
A12: =IF(F12<>0,1,0) -> 0 | D12: =IF(K12=0," ",K12) | F12: =N12 -> 0 | M12: 0 | N12: =M12*1+M12*$N$4 -> 0
A13: =IF(F13<>0,1,0) -> 0 | D13: =IF(K13=0," ",K13) | F13: =N13 -> 0 | M13: 0 | N13: =M13*1+M13*$N$4 -> 0
A14: =IF(F14<>0,1,0) -> 0 | D14: =IF(K14=0," ",K14) | F14: =N14 -> 0 | M14: 0 | N14: =M14*1+M14*$N$4 -> 0
A15: =IF(F15<>0,1,0) -> 0 | C15: Total: | D15: =IF(K15=0," ",K15) | F15: =N15 -> 0 | J15: Total: | M15: =SUM(M11:M14) -> 0 | N15: =SUM(N11:N14) -> 0
A16: =IF(F16<>0,1,0) -> 0 | C16: =J16 -> Alternate 02: | F16: =F21 -> 0 | J16: Alternate 02:
A17: =IF(F17<>0,1,0) -> 0 | D17: =IF(K17=0," ",K17) | F17: =N17 -> 0 | M17: 0 | N17: =M17*1+M17*$N$4 -> 0
A18: =IF(F18<>0,1,0) -> 0 | D18: =IF(K18=0," ",K18) | F18: =N18 -> 0 | M18: 0 | N18: =M18*1+M18*$N$4 -> 0
A19: =IF(F19<>0,1,0) -> 0 | D19: =IF(K19=0," ",K19) | F19: =N19 -> 0 | M19: 0 | N19: =M19*1+M19*$N$4 -> 0
A20: =IF(F20<>0,1,0) -> 0 | D20: =IF(K20=0," ",K20) | F20: =N20 -> 0 | M20: 0 | N20: =M20*1+M20*$N$4 -> 0
A21: =IF(F21<>0,1,0) -> 0 | C21: Total: | D21: =IF(K21=0," ",K21) | F21: =N21 -> 0 | J21: Total: | M21: =SUM(M17:M20) -> 0 | N21: =SUM(N17:N20) -> 0
A22: =IF(F22<>0,1,0) -> 1 | C22: =J22 -> Alternate 03: | F22: =F27 -> 551.1 | J22: Alternate 03:
A23: =IF(F23<>0,1,0) -> 1 | D23: =IF(K23=0," ",K23) | F23: =N23 -> 550 | M23: 500 | N23: =M23*1+M23*$N$4 -> 550
A24: =IF(F24<>0,1,0) -> 0 | D24: =IF(K24=0," ",K24) | F24: =N24 -> 0 | M24: 0 | N24: =M24*1+M24*$N$4 -> 0
A25: =IF(F25<>0,1,0) -> 0 | D25: =IF(K25=0," ",K25) | F25: =N25 -> 0 | M25: 0 | N25: =M25*1+M25*$N$4 -> 0
A26: =IF(F26<>0,1,0) -> 1 | D26: =IF(K26=0," ",K26) | F26: =N26 -> 1.1 | M26: 1 | N26: =M26*1+M26*$N$4 -> 1.1
A27: =IF(F27<>0,1,0) -> 1 | C27: Total: | D27: =IF(K27=0," ",K27) | F27: =N27 -> 551.1 | J27: Total: | M27: =SUM(M23:M26) -> 501 | N27: =SUM(N23:N26) -> 551.1
A28: =IF(F28<>0,1,0) -> 0 | C28: =J28 -> Alternate 04: | F28: =F33 -> 0 | J28: Alternate 04:
A29: =IF(F29<>0,1,0) -> 0 | D29: =IF(K29=0," ",K29) | F29: =N29 -> 0 | M29: 0 | N29: =M29*1+M29*$N$4 -> 0
A30: =IF(F30<>0,1,0) -> 0 | D30: =IF(K30=0," ",K30) | F30: =N30 -> 0 | M30: 0 | N30: =M30*1+M30*$N$4 -> 0
A31: =IF(F31<>0,1,0) -> 0 | D31: =IF(K31=0," ",K31) | F31: =N31 -> 0 | M31: 0 | N31: =M31*1+M31*$N$4 -> 0
A32: =IF(F32<>0,1,0) -> 0 | D32: =IF(K32=0," ",K32) | F32: =N32 -> 0 | M32: 0 | N32: =M32*1+M32*$N$4 -> 0
A33: =IF(F33<>0,1,0) -> 0 | C33: Total: | D33: =IF(K33=0," ",K33) | F33: =N33 -> 0 | J33: Total: | M33: =SUM(M29:M32) -> 0 | N33: =SUM(N29:N32) -> 0
A34: =IF(F34<>0,1,0) -> 0 | C34: =J34 -> Alternate 05: | F34: =F39 -> 0 | J34: Alternate 05:
A35: =IF(F35<>0,1,0) -> 0 | D35: =IF(K35=0," ",K35) | F35: =N35 -> 0 | M35: 0 | N35: =M35*1+M35*$N$4 -> 0
A36: =IF(F36<>0,1,0) -> 0 | D36: =IF(K36=0," ",K36) | F36: =N36 -> 0 | M36: 0 | N36: =M36*1+M36*$N$4 -> 0
A37: =IF(F37<>0,1,0) -> 0 | D37: =IF(K37=0," ",K37) | F37: =N37 -> 0 | M37: 0 | N37: =M37*1+M37*$N$4 -> 0
A38: =IF(F38<>0,1,0) -> 0 | D38: =IF(K38=0," ",K38) | F38: =N38 -> 0 | M38: 0 | N38: =M38*1+M38*$N$4 -> 0
A39: =IF(F39<>0,1,0) -> 0 | C39: Total: | D39: =IF(K39=0," ",K39) | F39: =N39 -> 0 | J39: Total: | M39: =SUM(M35:M38) -> 0 | N39: =SUM(N35:N38) -> 0
A40: =IF(F40<>0,1,0) -> 0 | C40: =J40 -> Alternate 06: | F40: =F45 -> 0 | J40: Alternate 06:
A41: =IF(F41<>0,1,0) -> 0 | D41: =IF(K41=0," ",K41) | F41: =N41 -> 0 | M41: 0 | N41: =M41*1+M41*$N$4 -> 0
A42: =IF(F42<>0,1,0) -> 0 | D42: =IF(K42=0," ",K42) | F42: =N42 -> 0 | M42: 0 | N42: =M42*1+M42*$N$4 -> 0
A43: =IF(F43<>0,1,0) -> 0 | D43: =IF(K43=0," ",K43) | F43: =N43 -> 0 | M43: 0 | N43: =M43*1+M43*$N$4 -> 0
A44: =IF(F44<>0,1,0) -> 0 | D44: =IF(K44=0," ",K44) | F44: =N44 -> 0 | M44: 0 | N44: =M44*1+M44*$N$4 -> 0
A45: =IF(F45<>0,1,0) -> 0 | C45: Total: | D45: =IF(K45=0," ",K45) | F45: =N45 -> 0 | J45: Total: | M45: =SUM(M41:M44) -> 0 | N45: =SUM(N41:N44) -> 0
...

Sheet WINTER CONDITIONS
C2: ='STEP 1 - PROJECT DATA'!D6& "." & 'STEP 1 - PROJECT DATA'!D7 -> E26-123.0
C3: ='STEP 1 - PROJECT DATA'!C5 -> Project Name | D3: ='STEP 1 - PROJECT DATA'!D5 -> Name | G3: Winter Conditions Estimate
C4: Location | D4: ='STEP 1 - PROJECT DATA'!D8 -> 1234 Main St
D5: ='STEP 1 - PROJECT DATA'!D9 -> Minneapolis, MN | E5: Actual | F5: Forecasted
C6: ='STEP 1 - PROJECT DATA'!C13 -> Architect | D6: ='STEP 1 - PROJECT DATA'!D13 -> TBD
C7: ='STEP 1 - PROJECT DATA'!C14 -> Plan Set | D7: ='STEP 1 - PROJECT DATA'!D14 -> TBD
E8: Season 1 | L8: Season 2
D9: Description | E9: Nov | F9: Dec | G9: Jan | H9: Feb | I9: Mar | J9: Apr | L9: Nov | M9: Dec | N9: Jan | O9: Feb | P9: Mar | Q9: Apr
C11: DIVISION 50 — WINTER CONDITIONS
E12: 0 | F12: 0 | G12: 0 | H12: 0 | I12: 0 | J12: 0 | L12: 0 | M12: 0 | N12: 0 | O12: 0 | P12: 0 | Q12: 0
C13: =C21+0.1 -> 50.2 | D13: Seasonal Rental Heaters | E13: 0 | F13: 0 | G13: 0 | H13: 0 | I13: 0 | J13: 0 | L13: 0 | M13: 0 | N13: 0 | O13: 0 | P13: 0 | Q13: 0
C14: =C17+0.1 -> 50.6 | D14: Rental Equipment | E14: 0 | F14: 0 | G14: 0 | H14: 0 | I14: 0 | J14: 0 | L14: 0 | M14: 0 | N14: 0 | O14: 0 | P14: 0 | Q14: 0
C15: =C13+0.1 -> 50.3 | D15: Plowing and Snow Removal | E15: 0 | F15: 0 | G15: 0 | H15: 0 | I15: 0 | J15: 0 | L15: 0 | M15: 0 | N15: 0 | O15: 0 | P15: 0 | Q15: 0
C16: =C15+0.1 -> 50.4 | D16: Concrete Subcontractor | E16: 0 | F16: 0 | G16: 0 | H16: 0 | I16: 0 | J16: 0 | L16: 0 | M16: 0 | N16: 0 | O16: 0 | P16: 0 | Q16: 0
C17: =C16+0.1 -> 50.5 | D17: Masonry Subcontractor | E17: 0 | F17: 0 | G17: 0 | H17: 0 | I17: 0 | J17: 0 | L17: 0 | M17: 0 | N17: 0 | O17: 0 | P17: 0 | Q17: 0
C18: =C12+0.1 -> 0.1 | D18: Mechanical Contractor | E18: 0 | F18: 0 | G18: 0 | H18: 0 | I18: 0 | J18: 0 | L18: 0 | M18: 0 | N18: 0 | O18: 0 | P18: 0 | Q18: 0
C19: 50.1 | D19: Earthwork Contractor | E19: 0 | F19: 0 | G19: 0 | H19: 0 | I19: 0 | J19: 0 | L19: 0 | M19: 0 | N19: 0 | O19: 0 | P19: 0 | Q19: 0
C20: =C14+0.1 -> 50.7 | D20: FP Labor | E20: 0 | F20: 0 | G20: 0 | H20: 0 | I20: 0 | J20: 0 | L20: 0 | M20: 0 | N20: 0 | O20: 0 | P20: 0 | Q20: 0
C21: 50.1 | D21: Natural Gas | E21: 0 | F21: 0 | G21: 0 | H21: 0 | I21: 0 | J21: 0 | L21: 0 | M21: 0 | N21: 0 | O21: 0 | P21: 0 | Q21: 0
C22: =C24+0.1 -> 50.9 | D22: Propane | E22: 0 | F22: 0 | G22: 0 | H22: 0 | I22: 0 | J22: 0 | L22: 0 | M22: 0 | N22: 0 | O22: 0 | P22: 0 | Q22: 0
C23: =C22+0.1 -> 51 | D23: Petroleum | E23: 0 | F23: 0 | G23: 0 | H23: 0 | I23: 0 | J23: 0 | L23: 0 | M23: 0 | N23: 0 | O23: 0 | P23: 0 | Q23: 0
C24: =C20+0.1 -> 50.8 | D24: Misc, Materials, Lumber, Poly | E24: 0 | F24: 0 | G24: 0 | H24: 0 | I24: 0 | J24: 0 | L24: 0 | M24: 0 | N24: 0 | O24: 0 | P24: 0 | Q24: 0
D25: Adjustment | E25: 0 | F25: 0 | G25: 0 | H25: 0 | I25: 0 | J25: 0 | L25: 0 | M25: 0 | N25: 0 | O25: 0 | P25: 0 | Q25: 0
E26: 0 | F26: 0 | G26: 0 | H26: 0 | I26: 0 | J26: 0 | L26: 0 | M26: 0 | N26: 0 | O26: 0 | P26: 0 | Q26: 0
D27: TOTALS | E27: =SUM(E12:E26) -> 0 | F27: =SUM(F12:F26) -> 0 | G27: =SUM(G12:G26) -> 0 | H27: =SUM(H12:H26) -> 0 | I27: =SUM(I12:I26) -> 0 | J27: =SUM(J12:J26) -> 0 | L27: =SUM(L12:L26) -> 0 | M27: =SUM(M12:M26) -> 0 | N27: =SUM(N12:N26) -> 0 | O27: =SUM(O12:O26) -> 0 | P27: =SUM(P12:P26) -> 0 | Q27: =SUM(Q12:Q26) -> 0
D31: Total Winter Conditions | F31: =SUM(E27:Q27) -> 0
D32: Allowance | F32: 0
D33: Net Change | F33: =F31-F32 -> 0

Sheet CLARIFICATIONS
C2: ='STEP 2 - GCs'!C2 -> E26-123.0
C3: ='STEP 2 - GCs'!C3 -> Project Name | D3: ='STEP 2 - GCs'!D3 -> Name
C4: ='STEP 2 - GCs'!C4 -> Location | D4: ='STEP 2 - GCs'!D4 -> 1234 Main St
D5: ='STEP 2 - GCs'!D5 -> Minneapolis, MN
C6: ='STEP 2 - GCs'!C6 -> Architect | D6: ='STEP 2 - GCs'!D6 -> TBD
C7: ='STEP 2 - GCs'!C7 -> Plan Set | D7: ='STEP 2 - GCs'!D7 -> TBD
C9: STANDARD CLARIFICATIONS AND EXCLUSIONS
C10: Handling or removal of hazardous materials.
C11: Builders Risk insurance policies.
C12: All bonds or any forms of security
C13: Special inspections and testing.
C14: Utility company charges of any kind. Any costs due to utility company requirements are not included.
C15: SAC / WAC fees or any governmental related fees other than the building permit.
C16: NPDES Permit.
C17: Soil corrections or buried debris / rubble.
C18: Design fees of any kind.
C19: Soil borings or geological reports.
C20: Miscellaneous site accessories including benches, bike racks, planters, and similar site elements.
... C35: PROJECT CLARIFICATIONS AND EXCLUSIONS

Sheet PER DIEM
M1: Low Risk
C2: ='STEP 1 - PROJECT DATA'!D6& "." & 'STEP 1 - PROJECT DATA'!D7 -> E26-123.0 | I2: ='STEP 4 - ESTIMATE'!I2 -> Bid Due Date | J2: ='STEP 4 - ESTIMATE'!K2 -> 46010 | M2: Medium Risk
C3: ='STEP 1 - PROJECT DATA'!C5 -> Project Name | D3: ='STEP 1 - PROJECT DATA'!D5 -> Name | E3: Per Diem | H3: ='STEP 1 - PROJECT DATA'!C10 -> Expected Start | J3: ='STEP 4 - ESTIMATE'!K3 -> 46174 | M3: High Risk
C4: Location | D4: ='STEP 1 - PROJECT DATA'!D8 -> 1234 Main St | H4: ='STEP 1 - PROJECT DATA'!C11 -> Expected Finish | J4: ='STEP 4 - ESTIMATE'!K4 -> 46235
D5: ='STEP 1 - PROJECT DATA'!D9 -> Minneapolis, MN | H5: Duration | J5: ='STEP 1 - PROJECT DATA'!D28 -> 2
C6: ='STEP 1 - PROJECT DATA'!C13 -> Architect | D6: ='STEP 1 - PROJECT DATA'!D13 -> TBD
C7: ='STEP 1 - PROJECT DATA'!C14 -> Plan Set | D7: ='STEP 1 - PROJECT DATA'!D14 -> TBD | J7: Bldg. Sqft.
J8: ='STEP 1 - PROJECT DATA'!D12 -> 10
C9: Code | D9: Description | E9: Utilization | F9: Quantity | G9: Unit | H9: Rate | I9: Total | J9: Cost/S.F.
C10: DIVISION 01 — SUPERVISION | D10: GENERAL CONDITIONS | E10: =SUM(I11:I15) -> 3464
C12: 01-0410 | D12: Sr Superintendent | E12: 1 | F12: =$J$5*4.33*40*E12 -> 346.4 | G12: hr | H12: 10 | I12: =F12*H12 -> 3464 | J12: =IF($J$8=0, 0, I12/$J$8) -> 346.4
C13: 01-0420 | D13: Superintendent | E13: 0 | F13: =$J$5*4.33*40*E13 -> 0 | G13: hr | H13: 10 | I13: =F13*H13 -> 0 | J13: =IF($J$8=0, 0, I13/$J$8) -> 0
C14: 01-0430 | D14: Asst. Superintendent | E14: 0 | F14: =$J$5*4.33*40*E14 -> 0 | G14: hr | H14: 10 | I14: =F14*H14 -> 0 | J14: =IF($J$8=0, 0, I14/$J$8) -> 0
C16: DIVISION 01 — PROJECT MANAGEMENT | D16: GENERAL CONDITIONS | E16: =SUM(I17:I23) -> 0
C18: 01-0310 | D18: Project Executive | E18: 0 | F18: =$J$5*4.33*40*E18 -> 0 | G18: hr | H18: 10 | I18: =F18*H18 -> 0 | J18: =IF($J$8=0, 0, I18/$J$8) -> 0
C19: 01-0320 | D19: Sr Project Manager | E19: 0 | F19: =$J$5*4.33*40*E19 -> 0 | G19: hr | H19: 10 | I19: =F19*H19 -> 0 | J19: =IF($J$8=0, 0, I19/$J$8) -> 0
C20: 01-0330 | D20: Project Manager | E20: 0 | F20: =$J$5*4.33*40*E20 -> 0 | G20: hr | H20: 10 | I20: =F20*H20 -> 0 | J20: =IF($J$8=0, 0, I20/$J$8) -> 0
C21: 01-0340 | D21: Project Engineer | E21: 0 | F21: =$J$5*4.33*40*E21 -> 0 | G21: hr | H21: 10 | I21: =F21*H21 -> 0 | J21: =IF($J$8=0, 0, I21/$J$8) -> 0
C22: 01-0510 | D22: Project Assistant | E22: 0 | F22: =$J$5*4.33*40*E22 -> 0 | G22: hr | H22: 10 | I22: =F22*H22 -> 0 | J22: =IF($J$8=0, 0, I22/$J$8) -> 0
C24: DIVISION 01 — FUEL AND VEHICLE CHARGES | D24: GENERAL CONDITIONS | E24: =SUM(I25:I35) -> 1701.69
C26: 01-1200 | D26: Fuel and Vehicle Charges
D27: Sr Superintendent | E27: 1 | F27: =$J$5*4.33*2*$D$60*E27 -> 2598 | G27: mi | H27: 0.655 | I27: =F27*H27 -> 1701.69 | J27: =IF($J$8=0, 0, I27/$J$8) -> 170.169
D28: Superintendent | E28: 0 | F28: =$J$5*4.33*2*$D$60*E28 -> 0 | G28: mi | H28: 0.655 | I28: =F28*H28 -> 0 | J28: =IF($J$8=0, 0, I28/$J$8) -> 0
D29: Asst. Superintendent | E29: 0 | F29: =$J$5*4.33*2*$D$60*E29 -> 0 | G29: mi | H29: 0.655 | I29: =F29*H29 -> 0 | J29: =IF($J$8=0, 0, I29/$J$8) -> 0
D30: Project Executive | E30: 0 | F30: =$J$5*4.33*2*$D$60*E30 -> 0 | G30: mi | H30: 0.655 | I30: =F30*H30 -> 0 | J30: =IF($J$8=0, 0, I30/$J$8) -> 0
D31: Sr Project Manager | E31: 0 | F31: =$J$5*4.33*2*$D$60*E31 -> 0 | G31: mi | H31: 0.655 | I31: =F31*H31 -> 0 | J31: =IF($J$8=0, 0, I31/$J$8) -> 0
D32: Project Manager | E32: 0 | F32: =$J$5*4.33*2*$D$60*E32 -> 0 | G32: mi | H32: 0.655 | I32: =F32*H32 -> 0 | J32: =IF($J$8=0, 0, I32/$J$8) -> 0
D33: Project Engineer | E33: 0 | F33: =$J$5*4.33*2*$D$60*E33 -> 0 | G33: mi | H33: 0.655 | I33: =F33*H33 -> 0 | J33: =IF($J$8=0, 0, I33/$J$8) -> 0
D34: Project Assistant | E34: 0 | F34: =$J$5*4.33*2*$D$60*E34 -> 0 | G34: mi | H34: 0.655 | I34: =F34*H34 -> 0 | J34: =IF($J$8=0, 0, I34/$J$8) -> 0
C36: DIVISION 01 — TRAVEL AND MEALS | D36: GENERAL CONDITIONS | E36: =SUM(I37:I47) -> 6495
C38: 01-1400 | D38: Travel and Meals
D39: Sr Superintendent | E39: 1 | F39: =$J$5*4.33*5*E39 -> 43.3 | G39: dy | H39: 150 | I39: =F39*H39 -> 6495 | J39: =IF($J$8=0, 0, I39/$J$8) -> 649.5
D40: Superintendent | E40: 0 | F40: =$J$5*4.33*5*E40 -> 0 | G40: dy | H40: 150 | I40: =F40*H40 -> 0 | J40: =IF($J$8=0, 0, I40/$J$8) -> 0
D41: Asst. Superintendent | E41: 0 | F41: =$J$5*4.33*5*E41 -> 0 | G41: dy | H41: 150 | I41: =F41*H41 -> 0 | J41: =IF($J$8=0, 0, I41/$J$8) -> 0
D42: Project Executive | E42: 0 | F42: =$J$5*4.33*5*E42 -> 0 | G42: dy | H42: 150 | I42: =F42*H42 -> 0 | J42: =IF($J$8=0, 0, I42/$J$8) -> 0
D43: Sr Project Manager | E43: 0 | F43: =$J$5*4.33*5*E43 -> 0 | G43: dy | H43: 150 | I43: =F43*H43 -> 0 | J43: =IF($J$8=0, 0, I43/$J$8) -> 0
D44: Project Manager | E44: 0 | F44: =$J$5*4.33*5*E44 -> 0 | G44: dy | H44: 150 | I44: =F44*H44 -> 0 | J44: =IF($J$8=0, 0, I44/$J$8) -> 0
D45: Project Engineer | E45: 0 | F45: =$J$5*4.33*5*E45 -> 0 | G45: dy | H45: 150 | I45: =F45*H45 -> 0 | J45: =IF($J$8=0, 0, I45/$J$8) -> 0
D46: Project Assistant | E46: 0 | F46: =$J$5*4.33*5*E46 -> 0 | G46: dy | H46: 150 | I46: =F46*H46 -> 0 | J46: =IF($J$8=0, 0, I46/$J$8) -> 0
H48: Total Per Diem | I48: =SUM(I11:I47) -> 11660.69 | J48: =IF($J$8=0, 0, I48/$J$8) -> 1166.069
...

Sheet TOWER CRANE
E1: Project Name:
E2: Location:
E3: Project Type:
E4: Date:
E5: Construction Duration:
D7: CRANE #1 | K7: CRANE #2
A9: Crane Duration | C9: 1 | D9: Months | H9: Crane Duration | J9: 1 | K9: Months
A10: Taxes | C10: 0.07125 | D10: Per Project Location | H10: Taxes | J10: 0.07125 | K10: Per Project Location
A12: ITEM DESCRIPTION | E12: Sub Name | H12: ITEM DESCRIPTION | L12: Sub Name
A14: Model | E14: Wolff WK325 | H14: Model | L14: Wolff WK325
A16: Hook Radius in feet | E16: 197 | H16: Hook Radius in feet | L16: 213
A18: Hook Height in feet | E18: 93 | H18: Hook Height in feet | L18: 197 or 211
A20: Crane Location (Grids) | E20: TBD | H20: Crane Location (Grids) | L20: TBD
A22: Erection and Dismantel Cost | E22: 64000 | H22: Erection and Dismantel Cost | L22: 139500
A24: Lease Rate per Month | D24: 13950 | H24: Lease Rate per Month | K24: 19950
A25: Months | D25: =$C$9 -> 1 | H25: Months | K25: =J9 -> 1
A26: Taxes | D26: =$C$10 -> 0.07125 | H26: Taxes | K26: =J10 -> 0.07125
A27: Total Lease Rate | E27: =(D24*D25)*(1+D26) -> 14943.938 | H27: Total Lease Rate | L27: =(K24*K25)*(1+K26) -> 21371.438
A29: Maintenance Rate per Month | D29: 700 | H29: Maintenance Rate per Month | K29: 700
A30: Months | D30: =$C$9 -> 1 | H30: Months | K30: =J9 -> 1
A31: Taxes | D31: =$C$10 -> 0.07125 | H31: Taxes | K31: =$C$10 -> 0.07125
A32: Total Maintenance Rate | E32: =(D29*D30)*(1+D31) -> 749.875 | H32: Total Maintenance Rate | L32: =(K29*K30)*(1+K31) -> 749.875
A34: Crane Base = poured concrete | E34: In Concrete | H34: Crane Base = poured concrete | L34: In Concrete
A36: Number of Piles | D36: 0 | H36: Number of Piles | K36: 0
A37: Cost Per Pile | D37: 1500 | H37: Cost Per Pile | K37: 1500
A38: Total Piling for the Crane Base | E38: =D37*D36 -> 0 | H38: Total Piling for the Crane Base | L38: =K37*K36 -> 0
A40: Electrical Hook-up | E40: In Electrical | H40: Electrical Hook-up | L40: In Electrical
A42: Electrical Power Usage | D42: 2000 | H42: Electrical Power Usage | K42: 2000
A43: Months | D43: =$C$9 -> 1 | H43: Months | K43: =J9 -> 1
A44: Total Electrical Power Usage | E44: =D43*D42 -> 2000 | H44: Total Electrical Power Usage | L44: =K43*K42 -> 2000
A46: Operator hrs/wk - Regular Rate | D46: 0 | H46: Operator hrs/wk - Regular Rate | K46: 0
A47: Operator Rate | D47: 82.92 | H47: Operator Rate | K47: 82.92
A48: Months | D48: =$C$9 -> 1 | H48: Months | K48: =J9 -> 1
A49: Operator Total - Regular Rate | E49: =(D48*4.33)*D47*D46 -> 0 | H49: Operator Total - Regular Rate | L49: =(K48*4.33)*K47*K46 -> 0
A51: Operator hrs/wk - Overtime | D51: 0 | H51: Operator hrs/wk - Overtime | K51: 0
A52: Operator Rate | D52: 110.93 | H52: Operator Rate | K52: 110.93
A53: Months | D53: =$C$9 -> 1 | H53: Months | K53: =J9 -> 1
A54: Operator Total - Overtime | E54: =(D53*4.33)*D52*D51 -> 0 | H54: Operator Total - Overtime | L54: =(K53*4.33)*K52*K51 -> 0
A56: Permits - Allowance | E56: 10000 | H56: Permits - Allowance | L56: 10000
A58: Signage | E58: 0 | H58: Signage | L58: 0
...

Sheet SKIP
E1: Project Name:
E2: Location:
E3: Project Type:
E4: Date:
E5: Construction Duration:
A7: Man/Material Hoist - Single Car | H7: Man/Material Hoist - Double Car
A9: Hoist Duration | C9: 0 | D9: Months | H9: Hoist Duration | J9: 15 | K9: Months
A10: Hoist Levels | C10: 0 | D10: Levels | H10: Hoist Levels | J10: 26 | K10: Levels
A11: Taxes | C11: 0.07125 | D11: Per Project Location | H11: Taxes | J11: 0.07125 | K11: Per Project Location
A13: ITEM DESCRIPTION | E13: Sub Name | H13: ITEM DESCRIPTION | L13: Sub Name
A15: Model | E15: Single Car | H15: Model | L15: Double Car
A17: Capacity | E17: 6000# | H17: Capacity | L17: 6000#
A19: Car Size | E19: 4'-8"x12'-4"x7'-6" | H19: Car Size | L19: 4'-8"x12'-4"x7'-2"
A21: Speed | E21: 150 ft/mn | H21: Speed | L21: 300 ft/mn
A23: Erection and Dismantel Cost | E23: 24250 | H23: Erection and Dismantel Cost | L23: 58000
A25: Lease Rate per Month | D25: 5500 | H25: Lease Rate per Month | K25: =15500+750 -> 16250
A26: Months | D26: =C9 -> 0 | H26: Months | K26: =J9 -> 15
A27: Taxes | D27: =C11 -> 0.07125 | H27: Taxes | K27: =J11 -> 0.07125
A28: Total Lease Rate | E28: =(D25*D26)*(1+D27) -> 0 | H28: Total Lease Rate | L28: =(K25*K26)*(1+K27) -> 261117.19
A30: Quarterly Inspections | D30: =C9/3 -> 0 | H30: Quarterly Inspections | K30: =J9/3 -> 5
A31: Quarterly Inspections Costs | D31: 1000 | H31: Quarterly Inspections Costs | K31: =130*2*6 -> 1560
A32: Total Quarterly Inspections | E32: =D31*D30 -> 0 | H32: Total Quarterly Inspections | L32: =K31*K30 -> 7800
A34: Maintenance Costs/Month | D34: 650 | H34: Maintenance Costs/Month | K34: 650
A35: Maintenance Months | D35: =C9 -> 0 | H35: Maintenance Months | K35: =J9 -> 15
A36: Maintenance Costs | E36: =D35*D34 -> 0 | H36: Maintenance Costs | L36: =K35*K34 -> 9750
A38: Number of Landing Gates | D38: =C10 -> 0 | H38: Number of Landing Gates | K38: =J10 -> 26
A39: Monthly Rental | D39: 155 | H39: Monthly Rental | K39: 155
A40: Months | D40: =C9 -> 0 | H40: Months | K40: =J9 -> 15
A41: Total Gates Costs | E41: =D40*D39*D38 -> 0 | H41: Total Gates Costs | L41: =K40*K39*K38 -> 60450
A43: Slab Extensions | E43: confirm | H43: Slab Extensions | L43: confirm
A45: Call System Rate | D45: 650 | H45: Call System Rate | K45: 1350
A46: Months | D46: =C9 -> 0 | H46: Months | K46: =J9 -> 15
A47: Total Call System | E47: =D46*D45 -> 0 | H47: Total Call System | L47: =K46*K45 -> 20250
A49: Hoist Base = poured concrete | E49: In Concrete | H49: Hoist Base = poured concrete | L49: In Concrete
A51: Number of Piles | D51: 0 | H51: Number of Piles | K51: 0
A52: Cost Per Pile | D52: 1500 | H52: Cost Per Pile | K52: 1500
A53: Total Piling for the Crane Base | E53: =D52*D51 -> 0 | H53: Total Piling for the Crane Base | L53: =K52*K51 -> 0
A55: Electrical Hook-up | E55: Included in Electrical | H55: Electrical Hook-up | L55: Included in Electrical
A57: Electrical Power Usage | D57: 1500 | H57: Electrical Power Usage | K57: 1500
A58: Months | D58: =C9 -> 0 | H58: Months | K58: =J9 -> 15
...

Sheet STREET CLOSURES
E1: Project Name:
E2: Location: | I2: https://www2.minneapolismn.gov/business-services/licenses-permits-inspections/streets-sidewalks-utility/city-lane-use-permits/lane-use-fee-changes/
E3: Project Type:
E4: Date:
E5: Construction Duration:
A7: Street Closures
A9: North Street Name: | G9: South Street Name:
A10: North Street Duration: | B10: 2 | C10: Months | G10: South Street Duration: | H10: 18 | I10: Months
A12: Type | B12: Months | C12: Length/Each | D12: $/FT-EA/Day | E12: Total | G12: Type | H12: Months | I12: Length/Each | J12: $/FT-EA/Day | K12: Total
A13: Moving Lane | B13: =B10 -> 2 | C13: 341 | D13: 0.5 | E13: =(B13*4.33*7)*C13*D13 -> 10335.71 | G13: Moving Lane | H13: =H10 -> 18 | I13: 0 | J13: 0.5 | K13: =(H13*4.33*7)*I13*J13 -> 0
A14: Parking | B14: =B10 -> 2 | C14: 0 | D14: 0.15 | E14: =(B14*4.33*7)*C14*D14 -> 0 | G14: Parking | H14: =H10 -> 18 | I14: 388 | J14: 0.15 | K14: =(H14*4.33*7)*I14*J14 -> 31752.756
A15: Sidewalk | B15: =B10 -> 2 | C15: 0 | D15: 0.15 | E15: =(B15*4.33*7)*C15*D15 -> 0 | G15: Sidewalk | H15: =H10 -> 18 | I15: 388 | J15: 0.15 | K15: =(H15*4.33*7)*I15*J15 -> 31752.756
A16: Bike Lane | B16: =B10 -> 2 | C16: 341 | D16: 0.15 | E16: =(B16*4.33*7)*C16*D16 -> 3100.713 | G16: Bike Lane | H16: =H10 -> 18 | I16: 0 | J16: 0.15 | K16: =(H16*4.33*7)*I16*J16 -> 0
A17: Alley | B17: =B10 -> 2 | C17: 0 | D17: 0.15 | E17: =(B17*4.33*7)*C17*D17 -> 0 | G17: Alley | H17: =H10 -> 18 | I17: 0 | J17: 0.15 | K17: =(H17*4.33*7)*I17*J17 -> 0
A18: Parking Meters | B18: =B10 -> 2 | C18: 0 | D18: 7.36 | E18: =(B18*4.33*7)*C18*D18 -> 0 | G18: Parking Meters | H18: =H10 -> 18 | I18: 13 | J18: 7.36 | K18: =(H18*4.33*7)*I18*J18 -> 52201.094
A19: Parking Meters Remove and Install Pipe | C19: 0 | D19: 100 | E19: =D19*C19 -> 0 | G19: Parking Meters Remove and Install Pipe | I19: 7 | J19: 100 | K19: =J19*I19 -> 700
A20: Subtotal North Street | E20: =SUM(E13:E19) -> 13436.423 | G20: Subtotal South Street | K20: =SUM(K13:K19) -> 116406.61
A22: West Street Name: | G22: East Street Name:
A23: West Street Duration: | B23: 20 | C23: Months | G23: East Street Duration: | H23: 24 | I23: Months
A25: Type | B25: Months | C25: Length/Each | D25: $/FT-EA/Day | E25: Total | G25: Type | H25: Months | I25: Length/Each | J25: $/FT-EA/Day | K25: Total
A26: Moving Lane | B26: =B23 -> 20 | C26: 0 | D26: 0.5 | E26: =(B26*4.33*7)*C26*D26 -> 0 | G26: Moving Lane | H26: =H23 -> 24 | I26: 0 | J26: 0.5 | K26: =(H26*4.33*7)*I26*J26 -> 0
A27: Parking | B27: =B23 -> 20 | C27: 0 | D27: 0.15 | E27: =(B27*4.33*7)*C27*D27 -> 0 | G27: Parking | H27: =H23 -> 24 | I27: 0 | J27: 0.15 | K27: =(H27*4.33*7)*I27*J27 -> 0
A28: Sidewalk | B28: =B23 -> 20 | C28: 0 | D28: 0.15 | E28: =(B28*4.33*7)*C28*D28 -> 0 | G28: Sidewalk | H28: =H23 -> 24 | I28: 0 | J28: 0.15 | K28: =(H28*4.33*7)*I28*J28 -> 0
A29: Bike Lane | B29: =B23 -> 20 | C29: 0 | D29: 0.15 | E29: =(B29*4.33*7)*C29*D29 -> 0 | G29: Bike Lane | H29: =H23 -> 24 | I29: 0 | J29: 0.15 | K29: =(H29*4.33*7)*I29*J29 -> 0
A30: Alley | B30: =B23 -> 20 | C30: 0 | D30: 0.15 | E30: =(B30*4.33*7)*C30*D30 -> 0 | G30: Alley | H30: =H23 -> 24 | I30: 0 | J30: 0.15 | K30: =(H30*4.33*7)*I30*J30 -> 0
A31: Parking Meters | B31: =B23 -> 20 | C31: 12 | D31: 7.36 | E31: =(B31*4.33*7)*C31*D31 -> 53539.584 | G31: Parking Meters | H31: =H23 -> 24 | I31: 23 | J31: 7.36 | K31: =(H31*4.33*7)*I31*J31 -> 123141.04
A32: Parking Meters Remove and Install Pipe | C32: 6 | D32: 100 | E32: =D32*C32 -> 600 | G32: Parking Meters Remove and Install Pipe | I32: 13 | J32: 100 | K32: =J32*I32 -> 1300
A33: Subtotal West Street | E33: =SUM(E26:E32) -> 54139.584 | G33: Subtotal East Street | K33: =SUM(K26:K32) -> 124441.04
A36: Grand Total | E36: =E20+E33+K20+K33 -> 308423.66
A38: Per Month- Based on the Total Project Duration | E38: =E36/G5 -> #DIV/0!
A41: Parking Meter Total | E41: =E32+E31+K19+K18+K32+K31 -> 231481.72
A42: Street Closures | E42: =E36-E41 -> 76941.935
A44: Previous Estimate | E44: 288000
A45: Difference | E45: =E36-E44 -> 20423.657

Sheet STORM RETENTION
A2: Building Permit Calculation
A4: Impervious Area (SF) | B4: 20000
A5: Rainfall (inches) | B5: 1
A6: Runoff Coefficient | B6: 0.9
A7: Conversion factor | B7: 0.623
A9: Storage Volume (Gallons) | C9: =B4*B5*B6*B7 -> 11214

Sheet Budget Line Items
A1: Cost Code | B1: Cost Type | C1: Description | D1: Manual Calculation | E1: Unit Qty | F1: UOM | G1: Unit Cost | H1: Budget Amount | I1: Start Date | J1: End Date | K1: Curve
A2: 1-10000.000 | B2: Material | C2: General Conditions | E2: 1 | F2: ls | H2: =SUMIF('STEP 2 - GCs'!$C$2:$C$603, 'STEP 2 - GCs'!#REF!, 'STEP 2 - GCs'!$I$2:$I$603) -> 0
A3: 1-10001.000 | B3: Material | C3: Preconstruction Fees | E3: 1 | F3: ls | H3: =SUMIF('STEP 2 - GCs'!$C$2:$C$603, 'STEP 2 - GCs'!C19, 'STEP 2 - GCs'!$I$2:$I$603) -> 0
A4: 1-10130.000 | B4: Material | C4: Design - Architecture | E4: 1 | F4: ls | H4: =SUMIF('STEP 2 - GCs'!$C$2:$C$603, 'STEP 2 - GCs'!C20, 'STEP 2 - GCs'!$I$2:$I$603) -> 0
A5: 1-10160.000 | B5: Material | C5: Design - Civil | E5: 1 | F5: ls | H5: =SUMIF('STEP 2 - GCs'!$C$2:$C$603, 'STEP 2 - GCs'!C21, 'STEP 2 - GCs'!$I$2:$I$603) -> 0
A6: 1-10180.000 | B6: Material | C6: Design - MEP | E6: 1 | F6: ls | H6: =SUMIF('STEP 2 - GCs'!$C$2:$C$603, 'STEP 2 - GCs'!C22, 'STEP 2 - GCs'!$I$2:$I$603) -> 0
A7: 1-10210.000 | B7: Material | C7: Design - Structural | E7: 1 | F7: ls | H7: =SUMIF('STEP 2 - GCs'!$C$2:$C$603, 'STEP 2 - GCs'!C23, 'STEP 2 - GCs'!$I$2:$I$603) -> 0
A8: 1-10230.000 | B8: Material | C8: Building Permit | E8: 1 | F8: ls | H8: =SUMIF('STEP 4 - ESTIMATE'!$C$2:$C$630, 'STEP 4 - ESTIMATE'!C327, 'STEP 4 - ESTIMATE'!$I$2:$I$630) -> 2742.531
A9: 1-10250.000 | B9: Material | C9: Demolition Permit | E9: 1 | F9: ls | H9: =SUMIF('STEP 4 - ESTIMATE'!$C$2:$C$630, 'STEP 4 - ESTIMATE'!C328, 'STEP 4 - ESTIMATE'!$I$2:$I$630) -> 0
A10: 1-10260.000 | B10: Material | C10: City Licenses/Misc Permits | E10: 1 | F10: ls | H10: =SUMIF('STEP 4 - ESTIMATE'!$C$2:$C$630, 'STEP 4 - ESTIMATE'!C329, 'STEP 4 - ESTIMATE'!$I$2:$I$630) -> 0
A11: 1-10310.000 | B11: Labor | C11: Project Executive | E11: 1 | F11: ls | H11: =SUMIF('STEP 2 - GCs'!$C$2:$C$603, 'STEP 2 - GCs'!C27, 'STEP 2 - GCs'!$I$2:$I$603) -> 0
A12: 1-10320.000 | B12: Labor | C12: Sr Project Manager | E12: 1 | F12: ls | H12: =SUMIF('STEP 2 - GCs'!$C$2:$C$603, 'STEP 2 - GCs'!C28, 'STEP 2 - GCs'!$I$2:$I$603) -> 23382
A13: 1-10330.000 | B13: Labor | C13: Project Manager | E13: 1 | F13: ls | H13: =SUMIF('STEP 2 - GCs'!$C$2:$C$603, 'STEP 2 - GCs'!C29, 'STEP 2 - GCs'!$I$2:$I$603) -> 0
A14: 1-10340.000 | B14: Labor | C14: Project Engineer | E14: 1 | F14: ls | H14: =SUMIF('STEP 2 - GCs'!$C$2:$C$603, 'STEP 2 - GCs'!C30, 'STEP 2 - GCs'!$I$2:$I$603) -> 0
A15: 1-10410.000 | B15: Labor | C15: Sr Superintendent | E15: 1 | F15: ls | H15: =SUMIF('STEP 2 - GCs'!$C$2:$C$603, 'STEP 2 - GCs'!C12, 'STEP 2 - GCs'!$I$2:$I$603) -> 43300
A16: 1-10420.000 | B16: Labor | C16: Superintendent | E16: 1 | F16: ls | H16: =SUMIF('STEP 2 - GCs'!$C$2:$C$603, 'STEP 2 - GCs'!C13, 'STEP 2 - GCs'!$I$2:$I$603) -> 0
A17: 1-10430.000 | B17: Labor | C17: Asst. Superintendent | E17: 1 | F17: ls | H17: =SUMIF('STEP 2 - GCs'!$C$2:$C$603, 'STEP 2 - GCs'!C14, 'STEP 2 - GCs'!$I$2:$I$603) -> 0
A18: 1-10510.000 | B18: Labor | C18: Project Assistant | E18: 1 | F18: ls | H18: =SUMIF('STEP 2 - GCs'!$C$2:$C$603, 'STEP 2 - GCs'!C31, 'STEP 2 - GCs'!$I$2:$I$603) -> 0
A19: 1-10610.000 | B19: Material | C19: Safety Consultant, Visit Bi-Weekly | E19: 1 | F19: ls | H19: =SUMIF('STEP 2 - GCs'!$C$2:$C$603, 'STEP 2 - GCs'!C35, 'STEP 2 - GCs'!$I$2:$I$603) -> 23.4778
A20: 1-11000.000 | B20: Material | C20: Small Tools | E20: 1 | F20: ls | H20: =SUMIF('STEP 2 - GCs'!$C$2:$C$603, 'STEP 2 - GCs'!C36, 'STEP 2 - GCs'!$I$2:$I$603) -> 1000
A21: 1-11200.000 | B21: Material | C21: Fuel and Vehicle Charges | E21: 1 | F21: ls | H21: =SUMIF('STEP 2 - GCs'!$C$2:$C$603, 'STEP 2 - GCs'!C37, 'STEP 2 - GCs'!$I$2:$I$603) -> 2400
A22: 1-11400.000 | B22: Material | C22: Travel and Meals | E22: 1 | F22: ls | H22: =SUMIF('STEP 2 - GCs'!$C$2:$C$603, 'STEP 2 - GCs'!C38, 'STEP 2 - GCs'!$I$2:$I$603) -> 0
A23: 1-11600.000 | B23: Material | C23: Procore | E23: 1 | F23: ls | H23: =SUMIF('STEP 2 - GCs'!$C$2:$C$603, 'STEP 2 - GCs'!C39, 'STEP 2 - GCs'!$I$2:$I$603) -> 223.0391
A24: 1-14010.000 | B24: Material | C24: Quality | E24: 1 | F24: ls | H24: =SUMIF('STEP 2 - GCs'!$C$2:$C$603, 'STEP 2 - GCs'!C40, 'STEP 2 - GCs'!$I$2:$I$603) -> 1000
A25: 1-15110.000 | B25: Material | C25: Temp Office and Set up | E25: 1 | F25: ls | H25: =SUMIF('STEP 2 - GCs'!$C$2:$C$603, 'STEP 2 - GCs'!C41, 'STEP 2 - GCs'!$I$2:$I$603) -> 10700
A26: 1-15111.000 | B26: Material | C26: Cell Phone | E26: 1 | F26: ls | H26: =SUMIF('STEP 2 - GCs'!$C$2:$C$603, 'STEP 2 - GCs'!C43, 'STEP 2 - GCs'!$I$2:$I$603) -> 270
A27: 1-15112.000 | B27: Material | C27: Jobsite Office Equipment | E27: 1 | F27: ls | H27: =SUMIF('STEP 2 - GCs'!$C$2:$C$603, 'STEP 2 - GCs'!C44, 'STEP 2 - GCs'!$I$2:$I$603) -> 500
A28: 1-15114.000 | B28: Material | C28: Project Computers / Internet | E28: 1 | F28: ls | H28: =SUMIF('STEP 2 - GCs'!$C$2:$C$603, 'STEP 2 - GCs'!C45, 'STEP 2 - GCs'!$I$2:$I$603) -> 600
A29: 1-15120.000 | B29: Material | C29: Storage Trailer | E29: 1 | F29: ls | H29: =SUMIF('STEP 2 - GCs'!$C$2:$C$603, 'STEP 2 - GCs'!C46, 'STEP 2 - GCs'!$I$2:$I$603) -> 1600
A30: 1-15130.000 | B30: Material | C30: Dumpsters | E30: 1 | F30: ls | H30: =SUMIF('STEP 2 - GCs'!$C$2:$C$603, 'STEP 2 - GCs'!C47, 'STEP 2 - GCs'!$I$2:$I$603) -> 5200
A31: 1-15140.000 | B31: Material | C31: Temporary Toilets | E31: 1 | F31: ls | H31: =SUMIF('STEP 2 - GCs'!$C$2:$C$603, 'STEP 2 - GCs'!C48, 'STEP 2 - GCs'!$I$2:$I$603) -> 2000
A32: 1-15150.000 | B32: Material | C32: Temporary Fire Extinguishers | E32: 1 | F32: ls | H32: =SUMIF('STEP 2 - GCs'!$C$2:$C$603, 'STEP 2 - GCs'!C49, 'STEP 2 - GCs'!$I$2:$I$603) -> 0.33333333
A33: 1-15160.000 | B33: Material | C33: Temporary Project Signs | E33: 1 | F33: ls | H33: =SUMIF('STEP 2 - GCs'!$C$2:$C$603, 'STEP 2 - GCs'!C50, 'STEP 2 - GCs'!$I$2:$I$603) -> 1500
A34: 1-15170.000 | B34: Material | C34: Temporary Electric | E34: 1 | F34: ls | H34: =SUMIF('STEP 2 - GCs'!$C$2:$C$603, 'STEP 2 - GCs'!C51, 'STEP 2 - GCs'!$I$2:$I$603) -> 5000
A35: 1-15180.000 | B35: Material | C35: Temporary Gas (not winter heat) | E35: 1 | F35: ls | H35: =SUMIF('STEP 2 - GCs'!$C$2:$C$603, 'STEP 2 - GCs'!C52, 'STEP 2 - GCs'!$I$2:$I$603) -> 1800
A36: 1-15190.000 | B36: Material | C36: Temporary Water | E36: 1 | F36: ls | H36: =SUMIF('STEP 2 - GCs'!$C$2:$C$603, 'STEP 2 - GCs'!C53, 'STEP 2 - GCs'!$I$2:$I$603) -> 1300
A37: 1-16010.000 | B37: Material | C37: Courier services | E37: 1 | F37: ls | H37: =SUMIF('STEP 2 - GCs'!$C$2:$C$603, 'STEP 2 - GCs'!C54, 'STEP 2 - GCs'!$I$2:$I$603) -> 700
... A39: 1-17010.000 | B39: Material | C39: Legal Fees | E39: 1 | F39: ls | H39: =SUMIF('STEP 2 - GCs'!$C$2:$C$603, 'STEP 2 - GCs'!C56, 'STEP 2 - GCs'!$I$2:$I$603) -> 5000
A40: 2-23200.000 | B40: Material | C40: Soil Borings | E40: 1 | F40: ls | H40: =SUMIF('STEP 3 - SITE OPS'!$C$2:$C$608, 'STEP 3 - SITE OPS'!C12, 'STEP 3 - SITE OPS'!$I$2:$I$608) -> 0
A41: 2-24100.000 | B41: Subcontract | C41: Demolition | E41: 1 | F41: ls | H41: =SUMIF('STEP 3 - SITE OPS'!$C$2:$C$608, 'STEP 3 - SITE OPS'!C32, 'STEP 3 - SITE OPS'!$I$2:$I$608) -> 0
...

Sheet Importer Data Fields
A1: Cost Code | B1: Cost Code Description | C1: Cost Type | D1: Cost Type Description | E1: BLI UOM | F1: BPQ UOM | G1: BOOLEAN
A2: 1-10000.000 | B2: General Conditions | C2: Equipment | D2: Equipment | E2: days | F2: ea | G2: True
A3: 1-10001.000 | B3: Preconstruction Fees | C3: Labor | D3: Labor | E3: hours | F3: ls | G3: False
A4: 1-10130.000 | B4: Design - Architecture | C4: Material | D4: Material | E4: months | F4: lf
A5: 1-10160.000 | B5: Design - Civil | C5: Other | D5: Other | E5: weeks | F5: m
A6: 1-10180.000 | B6: Design - MEP | C6: Subcontract | D6: Subcontract | E6: years | F6: mm
A7: 1-10210.000 | B7: Design - Structural | C7: User Def Type 6 | D7: User Def Type 6 | E7: ea | F7: m²
A8: 1-10230.000 | B8: Building Permit | C8: User Def Type 7 | D8: User Def Type 7 | E8: ls | F8: sf
A9: 1-10250.000 | B9: Demolition Permit | C9: User Def Type 8 | D9: User Def Type 8 | E9: lf | F9: sy
A10: 1-10260.000 | B10: City Licenses/Misc Permits | C10: User Def Type 9 | D10: User Def Type 9 | E10: m | F10: cy
A11: 1-10310.000 | B11: Project Executive | E11: mm | F11: m³
A12: 1-10320.000 | B12: Sr Project Manager | E12: m² | F12: kg
A13: 1-10330.000 | B13: Project Manager | E13: sf | F13: lbs
A14: 1-10340.000 | B14: Project Engineer | E14: sy | F14: t
A15: 1-10410.000 | B15: Sr Superintendent | E15: cy | F15: ton
A16: 1-10420.000 | B16: Superintendent | E16: m³
A17: 1-10430.000 | B17: Asst. Superintendent | E17: kg
A18: 1-10440.000 | B18: General Labor | E18: lbs
A19: 1-10510.000 | B19: Project Assistant | E19: t
A20: 1-10610.000 | B20: Safety Consultant, Visit Bi-Weekly | E20: ton
