Workbook

Sheet Project Info
B3: Project Owner:
B4: PROJECT NAME: | D4: NAME
B5: PROJECT DATE: | D5: DATE
B6: Project Address:
B7: Project Sqft:

Sheet INDEX
B2: Division | C2: Worksheet Name | D2: Link
B3: 02 | C3: 02-4100 Demolition | D3: Link
C4: 02-9005 Final Clean | D4: Link
C5: 02-9200 Survey | D5: Link
B6: 03 | C6: 03-3000 Concrete | D6: Link
C7: 03-4100 Precast Conc | D7: Link
C8: 03-5413 Gypcrete | D8: Link
B9: 04 | C9: 04-0000 Masonry | D9: Link
B10: 05 | C10: 05-1200 Struct Steel | D10: Link
C11: 05-7210 Alum Decks | D11: Link
B12: 06 | C12: 06-1000 Rough Carp | D12: Link
C13: 06-2000 Finish Carp | D13: Link
C14: 06-2200 Millwork | D14: Link
C15: 06-4100 Arch Casework | D15: Link
C16: 06-6116 Solid Surfaces | D16: Link
C17: 06-8700 Pergolas | D17: Link
B18: 07 | C18: 07-1000 Waterproofing | D18: Link
C19: 07-2100 Insulation | D19: Link
C20: 07-2500 Weather Barrier | D20: Link
C21: 07-3113 Asphalt Shingles | D21: Link
C22: 07-4213 Metal Panel Siding | D22: Link
C23: 07-4600 Siding | D23: Link
C24: 07-5000 Membrane Roofing | D24: Link
C25: 07-7600 Roof Pavers | D25: Link
C26: 07-6200 Metal Flashing | D26: Link
C27: 07-8100 Fire Proofing | D27: Link
C28: 07-9200 Joint Sealants | D28: Link
B29: 08 | C29: 08-1000 Doors, Frames, HW | D29: Link
C30: 08-3113 Access Panels | D30: Link
C31: 08-3613 Overhead Doors | D31: Link
C32: 08-4000 Alum Entr & Storefronts | D32: Link
C33: 08-5413 Windows & Patio Doors | D33: Link
C34: 08-8330 Mirrors | D34: Link
B35: 09 | C35: 09-2116 Gypsum Board Assemblies | D35: Link
C36: 09-2216 Steel Studs | D36: Link
C37: 09-3000 Tile | D37: Link
C38: 09-5113 Acoustical Tile Ceiling | D38: Link
C39: 09-6400 Wood Flooring | D39: Link
C40: 09-6500 Resilient Flooring | D40: Link
C41: 09-6600 Terrazzo Flooring | D41: Link
...

Sheet BLANK
B1: INDEX
B2: TYPE OF WORK: | D2: {=MID(CELL("filename", A1), FIND("]", CELL("filename", A1)) + 1, 255)} -> #VALUE! | H2: Apparent Low: | J2: VENDOR NUMBER | L2: 1 | N2: 2 | P2: 3 | R2: 4 | T2: 5 | V2: 6
B3: PROJECT NAME: | D3: ='Project Info'!D4 -> NAME | H3: {=IF(MIN(IF(M34:W34>0, M34:W34, ""))="", "", INDEX(L3:V3, MATCH(MIN(IF(M34:W34>0, M34:W34, "")), IF(MOD(COLUMN(M34:W34)-COLUMN(M34)+1, 2)=1, M34:W34, ""), 0)))} -> 0 | J3: NAME:
B4: PROJECT DATE: | D4: ='Project Info'!D5 -> DATE | J4: CONTACT:
J5: PHONE:
J6: EMAIL:
B7: BUDGET: | J7: DATE:
B8: LABOR | C8: MATERIAL | D8: SUB | E8: TOTAL | F8: COST CODE | G8: ITEM DESCRIPTION | J8: QUANTITY | K8: UNIT | L8: PRICE | M8: TOTAL | N8: PRICE | O8: TOTAL | P8: PRICE | Q8: TOTAL | R8: PRICE | S8: TOTAL | T8: PRICE | U8: TOTAL | V8: PRICE | W8: TOTAL
C9: LOW | D9: {=MIN(IF(M35:W35>0, M35:W35))} -> 0 | E9: =SUM(B9:D9) -> 0 | F9: 00-0000 | G9: Blank | M9: =L9*$J9 -> 0 | O9: =N9*$J9 -> 0 | Q9: =P9*$J9 -> 0 | S9: =R9*$J9 -> 0 | U9: =T9*$J9 -> 0 | W9: =V9*$J9 -> 0
E10: =SUM(B10:D10) -> 0 | M10: =L10*$J10 -> 0 | O10: =N10*$J10 -> 0 | Q10: =P10*$J10 -> 0 | S10: =R10*$J10 -> 0 | U10: =T10*$J10 -> 0 | W10: =V10*$J10 -> 0
E11: =SUM(B11:D11) -> 0 | M11: =L11*$J11 -> 0 | O11: =N11*$J11 -> 0 | Q11: =P11*$J11 -> 0 | S11: =R11*$J11 -> 0 | U11: =T11*$J11 -> 0 | W11: =V11*$J11 -> 0
E12: =SUM(B12:D12) -> 0 | M12: =L12*$J12 -> 0 | O12: =N12*$J12 -> 0 | Q12: =P12*$J12 -> 0 | S12: =R12*$J12 -> 0 | U12: =T12*$J12 -> 0 | W12: =V12*$J12 -> 0
E13: =SUM(B13:D13) -> 0 | M13: =L13*$J13 -> 0 | O13: =N13*$J13 -> 0 | Q13: =P13*$J13 -> 0 | S13: =R13*$J13 -> 0 | U13: =T13*$J13 -> 0 | W13: =V13*$J13 -> 0
E14: =SUM(B14:D14) -> 0 | M14: =L14*$J14 -> 0 | O14: =N14*$J14 -> 0 | Q14: =P14*$J14 -> 0 | S14: =R14*$J14 -> 0 | U14: =T14*$J14 -> 0 | W14: =V14*$J14 -> 0
E15: =SUM(B15:D15) -> 0 | M15: =L15*$J15 -> 0 | O15: =N15*$J15 -> 0 | Q15: =P15*$J15 -> 0 | S15: =R15*$J15 -> 0 | U15: =T15*$J15 -> 0 | W15: =V15*$J15 -> 0
E16: =SUM(B16:D16) -> 0 | M16: =L16*$J16 -> 0 | O16: =N16*$J16 -> 0 | Q16: =P16*$J16 -> 0 | S16: =R16*$J16 -> 0 | U16: =T16*$J16 -> 0 | W16: =V16*$J16 -> 0
E17: =SUM(B17:D17) -> 0 | M17: =L17*$J17 -> 0 | O17: =N17*$J17 -> 0 | Q17: =P17*$J17 -> 0 | S17: =R17*$J17 -> 0 | U17: =T17*$J17 -> 0 | W17: =V17*$J17 -> 0
E18: =SUM(B18:D18) -> 0 | M18: =L18*$J18 -> 0 | O18: =N18*$J18 -> 0 | Q18: =P18*$J18 -> 0 | S18: =R18*$J18 -> 0 | U18: =T18*$J18 -> 0 | W18: =V18*$J18 -> 0
E19: =SUM(B19:D19) -> 0 | M19: =L19*$J19 -> 0 | O19: =N19*$J19 -> 0 | Q19: =P19*$J19 -> 0 | S19: =R19*$J19 -> 0 | U19: =T19*$J19 -> 0 | W19: =V19*$J19 -> 0
E20: =SUM(B20:D20) -> 0 | M20: =L20*$J20 -> 0 | O20: =N20*$J20 -> 0 | Q20: =P20*$J20 -> 0 | S20: =R20*$J20 -> 0 | U20: =T20*$J20 -> 0 | W20: =V20*$J20 -> 0
E21: =SUM(B21:D21) -> 0 | M21: =L21*$J21 -> 0 | O21: =N21*$J21 -> 0 | Q21: =P21*$J21 -> 0 | S21: =R21*$J21 -> 0 | U21: =T21*$J21 -> 0 | W21: =V21*$J21 -> 0
... E31: =SUM(B31:D31) -> 0 | M31: =L31*$J31 -> 0 | O31: =N31*$J31 -> 0 | Q31: =P31*$J31 -> 0 | S31: =R31*$J31 -> 0 | U31: =T31*$J31 -> 0 | W31: =V31*$J31 -> 0
B32: =SUM(B9:B31) -> 0 | C32: =SUM(C9:C31) -> 0 | D32: =SUM(D9:D31) -> 0 | E32: =SUM(E9:E31) -> 0 | G32: SUBTOTAL | M32: =SUM(M9:M31) -> 0 | O32: =SUM(O9:O31) -> 0 | Q32: =SUM(Q9:Q31) -> 0 | S32: =SUM(S9:S31) -> 0 | U32: =SUM(U9:U31) -> 0 | W32: =SUM(W9:W31) -> 0
G33: TAX RATE % | M33: =$C$41 -> 0 | O33: =$C$41 -> 0 | Q33: =$C$41 -> 0 | S33: =$C$41 -> 0 | U33: =$C$41 -> 0 | W33: =$C$41 -> 0
G34: TOTAL TAX | M34: =M32*M33 -> 0 | O34: =O32*O33 -> 0 | Q34: =Q32*Q33 -> 0 | S34: =S32*S33 -> 0 | U34: =U32*U33 -> 0 | W34: =W32*W33 -> 0
B35: =B32 -> 0 | C35: =C32 -> 0 | D35: =D32 -> 0 | E35: =SUM(E32) -> 0 | G35: GRAND TOTAL | M35: =SUM(M32,M34) -> 0 | O35: =SUM(O32,O34) -> 0 | Q35: =SUM(Q32,Q34) -> 0 | S35: =SUM(S32,S34) -> 0 | U35: =SUM(U32,U34) -> 0 | W35: =SUM(W32,W34) -> 0
G36: BUDGET - OVER/(UNDER) | M36: =M35-$E$35 -> 0 | O36: =O35-$E$35 -> 0 | Q36: =Q35-$E$35 -> 0 | S36: =S35-$E$35 -> 0 | U36: =U35-$E$35 -> 0 | W36: =W35-$E$35 -> 0
G37: BUDGET - OVER/(UNDER) % | M37: =M36 / $E$35 -> #DIV/0! | O37: =O36 / $E$35 -> #DIV/0! | Q37: =Q36 / $E$35 -> #DIV/0! | S37: =S36 / $E$35 -> #DIV/0! | U37: =U36 / $E$35 -> #DIV/0! | W37: =W36 / $E$35 -> #DIV/0!
B41: TAX RATE | C41: 0

Sheet 02-4100 Demolition
B1: INDEX
B2: TYPE OF WORK: | D2: {=MID(CELL("filename", A1), FIND("]", CELL("filename", A1)) + 1, 255)} -> #VALUE! | J2: VENDOR NUMBER | L2: 1 | N2: 2 | P2: 3 | R2: 4 | T2: 5 | V2: 6
B3: PROJECT NAME: | D3: ='Project Info'!D4 -> NAME | J3: NAME:
B4: PROJECT DATE: | D4: ='Project Info'!D5 -> DATE | J4: CONTACT:
J5: PHONE:
J6: EMAIL:
B7: BUDGET: | J7: DATE:
B8: LABOR | C8: MATERIAL | D8: SUB | E8: TOTAL | F8: COST CODE | G8: ITEM DESCRIPTION | J8: QUANTITY | K8: UNIT | L8: PRICE | M8: TOTAL | N8: PRICE | O8: TOTAL | P8: PRICE | Q8: TOTAL | R8: PRICE | S8: TOTAL | T8: PRICE | U8: TOTAL | V8: PRICE | W8: TOTAL
C9: LOW | D9: {=MIN(IF(M35:W35>0, M35:W35))} -> 0 | E9: =SUM(B9:D9) -> 0 | F9: 02-4100 | G9: Demolition | M9: =L9*$J9 -> 0 | O9: =N9*$J9 -> 0 | Q9: =P9*$J9 -> 0 | S9: =R9*$J9 -> 0 | U9: =T9*$J9 -> 0 | W9: =V9*$J9 -> 0
E10: =SUM(B10:D10) -> 0 | M10: =L10*$J10 -> 0 | O10: =N10*$J10 -> 0 | Q10: =P10*$J10 -> 0 | S10: =R10*$J10 -> 0 | U10: =T10*$J10 -> 0 | W10: =V10*$J10 -> 0
E11: =SUM(B11:D11) -> 0 | G11: Floor grinding | M11: =L11*$J11 -> 0 | O11: =N11*$J11 -> 0 | Q11: =P11*$J11 -> 0 | S11: =R11*$J11 -> 0 | U11: =T11*$J11 -> 0 | W11: =V11*$J11 -> 0
E12: =SUM(B12:D12) -> 0 | M12: =L12*$J12 -> 0 | O12: =N12*$J12 -> 0 | Q12: =P12*$J12 -> 0 | S12: =R12*$J12 -> 0 | U12: =T12*$J12 -> 0 | W12: =V12*$J12 -> 0
E13: =SUM(B13:D13) -> 0 | M13: =L13*$J13 -> 0 | O13: =N13*$J13 -> 0 | Q13: =P13*$J13 -> 0 | S13: =R13*$J13 -> 0 | U13: =T13*$J13 -> 0 | W13: =V13*$J13 -> 0
E14: =SUM(B14:D14) -> 0 | M14: =L14*$J14 -> 0 | O14: =N14*$J14 -> 0 | Q14: =P14*$J14 -> 0 | S14: =R14*$J14 -> 0 | U14: =T14*$J14 -> 0 | W14: =V14*$J14 -> 0
E15: =SUM(B15:D15) -> 0 | M15: =L15*$J15 -> 0 | O15: =N15*$J15 -> 0 | Q15: =P15*$J15 -> 0 | S15: =R15*$J15 -> 0 | U15: =T15*$J15 -> 0 | W15: =V15*$J15 -> 0
E16: =SUM(B16:D16) -> 0 | M16: =L16*$J16 -> 0 | O16: =N16*$J16 -> 0 | Q16: =P16*$J16 -> 0 | S16: =R16*$J16 -> 0 | U16: =T16*$J16 -> 0 | W16: =V16*$J16 -> 0
E17: =SUM(B17:D17) -> 0 | M17: =L17*$J17 -> 0 | O17: =N17*$J17 -> 0 | Q17: =P17*$J17 -> 0 | S17: =R17*$J17 -> 0 | U17: =T17*$J17 -> 0 | W17: =V17*$J17 -> 0
E18: =SUM(B18:D18) -> 0 | M18: =L18*$J18 -> 0 | O18: =N18*$J18 -> 0 | Q18: =P18*$J18 -> 0 | S18: =R18*$J18 -> 0 | U18: =T18*$J18 -> 0 | W18: =V18*$J18 -> 0
E19: =SUM(B19:D19) -> 0 | M19: =L19*$J19 -> 0 | O19: =N19*$J19 -> 0 | Q19: =P19*$J19 -> 0 | S19: =R19*$J19 -> 0 | U19: =T19*$J19 -> 0 | W19: =V19*$J19 -> 0
E20: =SUM(B20:D20) -> 0 | M20: =L20*$J20 -> 0 | O20: =N20*$J20 -> 0 | Q20: =P20*$J20 -> 0 | S20: =R20*$J20 -> 0 | U20: =T20*$J20 -> 0 | W20: =V20*$J20 -> 0
E21: =SUM(B21:D21) -> 0 | M21: =L21*$J21 -> 0 | O21: =N21*$J21 -> 0 | Q21: =P21*$J21 -> 0 | S21: =R21*$J21 -> 0 | U21: =T21*$J21 -> 0 | W21: =V21*$J21 -> 0
E22: =SUM(B22:D22) -> 0 | M22: =L22*$J22 -> 0 | O22: =N22*$J22 -> 0 | Q22: =P22*$J22 -> 0 | S22: =R22*$J22 -> 0 | U22: =T22*$J22 -> 0 | W22: =V22*$J22 -> 0
E23: =SUM(B23:D23) -> 0 | M23: =L23*$J23 -> 0 | O23: =N23*$J23 -> 0 | Q23: =P23*$J23 -> 0 | S23: =R23*$J23 -> 0 | U23: =T23*$J23 -> 0 | W23: =V23*$J23 -> 0
... E31: =SUM(B31:D31) -> 0 | M31: =L31*$J31 -> 0 | O31: =N31*$J31 -> 0 | Q31: =P31*$J31 -> 0 | S31: =R31*$J31 -> 0 | U31: =T31*$J31 -> 0 | W31: =V31*$J31 -> 0
B32: =SUM(B9:B31) -> 0 | C32: =SUM(C9:C31) -> 0 | D32: =SUM(D9:D31) -> 0 | E32: =SUM(E9:E31) -> 0 | G32: SUBTOTAL | M32: =SUM(M9:M31) -> 0 | O32: =SUM(O9:O31) -> 0 | Q32: =SUM(Q9:Q31) -> 0 | S32: =SUM(S9:S31) -> 0 | U32: =SUM(U9:U31) -> 0 | W32: =SUM(W9:W31) -> 0
G33: TAX RATE % | M33: =$C$41 -> 0 | O33: =$C$41 -> 0 | Q33: =$C$41 -> 0 | S33: =$C$41 -> 0 | U33: =$C$41 -> 0 | W33: =$C$41 -> 0
G34: TOTAL TAX | M34: =M32*M33 -> 0 | O34: =O32*O33 -> 0 | Q34: =Q32*Q33 -> 0 | S34: =S32*S33 -> 0 | U34: =U32*U33 -> 0 | W34: =W32*W33 -> 0
B35: =B32 -> 0 | C35: =C32 -> 0 | D35: =D32 -> 0 | E35: =SUM(E32) -> 0 | G35: GRAND TOTAL | M35: =SUM(M32,M34) -> 0 | O35: =SUM(O32,O34) -> 0 | Q35: =SUM(Q32,Q34) -> 0 | S35: =SUM(S32,S34) -> 0 | U35: =SUM(U32,U34) -> 0 | W35: =SUM(W32,W34) -> 0
G36: BUDGET - OVER/(UNDER) | M36: =M35-$E$35 -> 0 | O36: =O35-$E$35 -> 0 | Q36: =Q35-$E$35 -> 0 | S36: =S35-$E$35 -> 0 | U36: =U35-$E$35 -> 0 | W36: =W35-$E$35 -> 0
G37: BUDGET - OVER/(UNDER) % | M37: =M36 / $E$35 -> #DIV/0! | O37: =O36 / $E$35 -> #DIV/0! | Q37: =Q36 / $E$35 -> #DIV/0! | S37: =S36 / $E$35 -> #DIV/0! | U37: =U36 / $E$35 -> #DIV/0! | W37: =W36 / $E$35 -> #DIV/0!
B41: TAX RATE | C41: 0

Sheet 02-9005 Final Clean
B1: INDEX
B2: TYPE OF WORK: | D2: {=MID(CELL("filename", A1), FIND("]", CELL("filename", A1)) + 1, 255)} -> #VALUE! | J2: VENDOR NUMBER | L2: 1 | N2: 2 | P2: 3 | R2: 4 | T2: 5 | V2: 6
B3: PROJECT NAME: | D3: ='Project Info'!D4 -> NAME | J3: NAME:
B4: PROJECT DATE: | D4: ='Project Info'!D5 -> DATE | J4: CONTACT:
J5: PHONE:
J6: EMAIL:
B7: BUDGET: | J7: DATE:
B8: LABOR | C8: MATERIAL | D8: SUB | E8: TOTAL | F8: COST CODE | G8: ITEM DESCRIPTION | J8: QUANTITY | K8: UNIT | L8: PRICE | M8: TOTAL | N8: PRICE | O8: TOTAL | P8: PRICE | Q8: TOTAL | R8: PRICE | S8: TOTAL | T8: PRICE | U8: TOTAL | V8: PRICE | W8: TOTAL
C9: LOW | D9: {=MIN(IF(M35:W35>0, M35:W35))} -> 0 | E9: =SUM(B9:D9) -> 0 | F9: 02-9005 | G9: Final Clean | M9: =L9*$J9 -> 0 | O9: =N9*$J9 -> 0 | Q9: =P9*$J9 -> 0 | S9: =R9*$J9 -> 0 | U9: =T9*$J9 -> 0 | W9: =V9*$J9 -> 0
E10: =SUM(B10:D10) -> 0 | M10: =L10*$J10 -> 0 | O10: =N10*$J10 -> 0 | Q10: =P10*$J10 -> 0 | S10: =R10*$J10 -> 0 | U10: =T10*$J10 -> 0 | W10: =V10*$J10 -> 0
E11: =SUM(B11:D11) -> 0 | G11: 3 Cleans | M11: =L11*$J11 -> 0 | O11: =N11*$J11 -> 0 | Q11: =P11*$J11 -> 0 | S11: =R11*$J11 -> 0 | U11: =T11*$J11 -> 0 | W11: =V11*$J11 -> 0
E12: =SUM(B12:D12) -> 0 | G12: Rough Clean | M12: =L12*$J12 -> 0 | O12: =N12*$J12 -> 0 | Q12: =P12*$J12 -> 0 | S12: =R12*$J12 -> 0 | U12: =T12*$J12 -> 0 | W12: =V12*$J12 -> 0
E13: =SUM(B13:D13) -> 0 | G13: Final Clean | M13: =L13*$J13 -> 0 | O13: =N13*$J13 -> 0 | Q13: =P13*$J13 -> 0 | S13: =R13*$J13 -> 0 | U13: =T13*$J13 -> 0 | W13: =V13*$J13 -> 0
E14: =SUM(B14:D14) -> 0 | G14: Shine Clean | M14: =L14*$J14 -> 0 | O14: =N14*$J14 -> 0 | Q14: =P14*$J14 -> 0 | S14: =R14*$J14 -> 0 | U14: =T14*$J14 -> 0 | W14: =V14*$J14 -> 0
E15: =SUM(B15:D15) -> 0 | M15: =L15*$J15 -> 0 | O15: =N15*$J15 -> 0 | Q15: =P15*$J15 -> 0 | S15: =R15*$J15 -> 0 | U15: =T15*$J15 -> 0 | W15: =V15*$J15 -> 0
E16: =SUM(B16:D16) -> 0 | G16: Exterior window cleaning | M16: =L16*$J16 -> 0 | O16: =N16*$J16 -> 0 | Q16: =P16*$J16 -> 0 | S16: =R16*$J16 -> 0 | U16: =T16*$J16 -> 0 | W16: =V16*$J16 -> 0
E17: =SUM(B17:D17) -> 0 | M17: =L17*$J17 -> 0 | O17: =N17*$J17 -> 0 | Q17: =P17*$J17 -> 0 | S17: =R17*$J17 -> 0 | U17: =T17*$J17 -> 0 | W17: =V17*$J17 -> 0
E18: =SUM(B18:D18) -> 0 | G18: Sweep and powerwash garage up 4' | M18: =L18*$J18 -> 0 | O18: =N18*$J18 -> 0 | Q18: =P18*$J18 -> 0 | S18: =R18*$J18 -> 0 | U18: =T18*$J18 -> 0 | W18: =V18*$J18 -> 0
E19: =SUM(B19:D19) -> 0 | M19: =L19*$J19 -> 0 | O19: =N19*$J19 -> 0 | Q19: =P19*$J19 -> 0 | S19: =R19*$J19 -> 0 | U19: =T19*$J19 -> 0 | W19: =V19*$J19 -> 0
E20: =SUM(B20:D20) -> 0 | M20: =L20*$J20 -> 0 | O20: =N20*$J20 -> 0 | Q20: =P20*$J20 -> 0 | S20: =R20*$J20 -> 0 | U20: =T20*$J20 -> 0 | W20: =V20*$J20 -> 0
E21: =SUM(B21:D21) -> 0 | M21: =L21*$J21 -> 0 | O21: =N21*$J21 -> 0 | Q21: =P21*$J21 -> 0 | S21: =R21*$J21 -> 0 | U21: =T21*$J21 -> 0 | W21: =V21*$J21 -> 0
E22: =SUM(B22:D22) -> 0 | M22: =L22*$J22 -> 0 | O22: =N22*$J22 -> 0 | Q22: =P22*$J22 -> 0 | S22: =R22*$J22 -> 0 | U22: =T22*$J22 -> 0 | W22: =V22*$J22 -> 0
E23: =SUM(B23:D23) -> 0 | M23: =L23*$J23 -> 0 | O23: =N23*$J23 -> 0 | Q23: =P23*$J23 -> 0 | S23: =R23*$J23 -> 0 | U23: =T23*$J23 -> 0 | W23: =V23*$J23 -> 0
E24: =SUM(B24:D24) -> 0 | M24: =L24*$J24 -> 0 | O24: =N24*$J24 -> 0 | Q24: =P24*$J24 -> 0 | S24: =R24*$J24 -> 0 | U24: =T24*$J24 -> 0 | W24: =V24*$J24 -> 0
E25: =SUM(B25:D25) -> 0 | M25: =L25*$J25 -> 0 | O25: =N25*$J25 -> 0 | Q25: =P25*$J25 -> 0 | S25: =R25*$J25 -> 0 | U25: =T25*$J25 -> 0 | W25: =V25*$J25 -> 0
E26: =SUM(B26:D26) -> 0 | M26: =L26*$J26 -> 0 | O26: =N26*$J26 -> 0 | Q26: =P26*$J26 -> 0 | S26: =R26*$J26 -> 0 | U26: =T26*$J26 -> 0 | W26: =V26*$J26 -> 0
E27: =SUM(B27:D27) -> 0 | M27: =L27*$J27 -> 0 | O27: =N27*$J27 -> 0 | Q27: =P27*$J27 -> 0 | S27: =R27*$J27 -> 0 | U27: =T27*$J27 -> 0 | W27: =V27*$J27 -> 0
E28: =SUM(B28:D28) -> 0 | M28: =L28*$J28 -> 0 | O28: =N28*$J28 -> 0 | Q28: =P28*$J28 -> 0 | S28: =R28*$J28 -> 0 | U28: =T28*$J28 -> 0 | W28: =V28*$J28 -> 0
E29: =SUM(B29:D29) -> 0 | M29: =L29*$J29 -> 0 | O29: =N29*$J29 -> 0 | Q29: =P29*$J29 -> 0 | S29: =R29*$J29 -> 0 | U29: =T29*$J29 -> 0 | W29: =V29*$J29 -> 0
E30: =SUM(B30:D30) -> 0 | M30: =L30*$J30 -> 0 | O30: =N30*$J30 -> 0 | Q30: =P30*$J30 -> 0 | S30: =R30*$J30 -> 0 | U30: =T30*$J30 -> 0 | W30: =V30*$J30 -> 0
E31: =SUM(B31:D31) -> 0 | M31: =L31*$J31 -> 0 | O31: =N31*$J31 -> 0 | Q31: =P31*$J31 -> 0 | S31: =R31*$J31 -> 0 | U31: =T31*$J31 -> 0 | W31: =V31*$J31 -> 0
B32: =SUM(B9:B31) -> 0 | C32: =SUM(C9:C31) -> 0 | D32: =SUM(D9:D31) -> 0 | E32: =SUM(E9:E31) -> 0 | G32: SUBTOTAL | M32: =SUM(M9:M31) -> 0 | O32: =SUM(O9:O31) -> 0 | Q32: =SUM(Q9:Q31) -> 0 | S32: =SUM(S9:S31) -> 0 | U32: =SUM(U9:U31) -> 0 | W32: =SUM(W9:W31) -> 0
G33: TAX RATE % | M33: =$C$41 -> 0 | O33: =$C$41 -> 0 | Q33: =$C$41 -> 0 | S33: =$C$41 -> 0 | U33: =$C$41 -> 0 | W33: =$C$41 -> 0
G34: TOTAL TAX | M34: =M32*M33 -> 0 | O34: =O32*O33 -> 0 | Q34: =Q32*Q33 -> 0 | S34: =S32*S33 -> 0 | U34: =U32*U33 -> 0 | W34: =W32*W33 -> 0
B35: =B32 -> 0 | C35: =C32 -> 0 | D35: =D32 -> 0 | E35: =SUM(E32) -> 0 | G35: GRAND TOTAL | M35: =SUM(M32,M34) -> 0 | O35: =SUM(O32,O34) -> 0 | Q35: =SUM(Q32,Q34) -> 0 | S35: =SUM(S32,S34) -> 0 | U35: =SUM(U32,U34) -> 0 | W35: =SUM(W32,W34) -> 0
G36: BUDGET - OVER/(UNDER) | M36: =M35-$E$35 -> 0 | O36: =O35-$E$35 -> 0 | Q36: =Q35-$E$35 -> 0 | S36: =S35-$E$35 -> 0 | U36: =U35-$E$35 -> 0 | W36: =W35-$E$35 -> 0
G37: BUDGET - OVER/(UNDER) % | M37: =M36 / $E$35 -> #DIV/0! | O37: =O36 / $E$35 -> #DIV/0! | Q37: =Q36 / $E$35 -> #DIV/0! | S37: =S36 / $E$35 -> #DIV/0! | U37: =U36 / $E$35 -> #DIV/0! | W37: =W36 / $E$35 -> #DIV/0!
B41: TAX RATE | C41: 0

Sheet 02-9200 Survey
B1: INDEX
B2: TYPE OF WORK: | D2: {=MID(CELL("filename", A1), FIND("]", CELL("filename", A1)) + 1, 255)} -> #VALUE! | J2: VENDOR NUMBER | L2: 1 | N2: 2 | P2: 3 | R2: 4 | T2: 5 | V2: 6
B3: PROJECT NAME: | D3: ='Project Info'!D4 -> NAME | J3: NAME:
B4: PROJECT DATE: | D4: ='Project Info'!D5 -> DATE | J4: CONTACT:
J5: PHONE:
J6: EMAIL:
B7: BUDGET: | J7: DATE:
B8: LABOR | C8: MATERIAL | D8: SUB | E8: TOTAL | F8: COST CODE | G8: ITEM DESCRIPTION | J8: QUANTITY | K8: UNIT | L8: PRICE | M8: TOTAL | N8: PRICE | O8: TOTAL | P8: PRICE | Q8: TOTAL | R8: PRICE | S8: TOTAL | T8: PRICE | U8: TOTAL | V8: PRICE | W8: TOTAL
C9: LOW | D9: {=MIN(IF(M35:W35>0, M35:W35))} -> 0 | E9: =SUM(B9:D9) -> 0 | F9: 02-9200 | G9: Survey | M9: =L9*$J9 -> 0 | O9: =N9*$J9 -> 0 | Q9: =P9*$J9 -> 0 | S9: =R9*$J9 -> 0 | U9: =T9*$J9 -> 0 | W9: =V9*$J9 -> 0
E10: =SUM(B10:D10) -> 0 | M10: =L10*$J10 -> 0 | O10: =N10*$J10 -> 0 | Q10: =P10*$J10 -> 0 | S10: =R10*$J10 -> 0 | U10: =T10*$J10 -> 0 | W10: =V10*$J10 -> 0
E11: =SUM(B11:D11) -> 0 | G11: Grading | M11: =L11*$J11 -> 0 | O11: =N11*$J11 -> 0 | Q11: =P11*$J11 -> 0 | S11: =R11*$J11 -> 0 | U11: =T11*$J11 -> 0 | W11: =V11*$J11 -> 0
E12: =SUM(B12:D12) -> 0 | G12: Utilities | M12: =L12*$J12 -> 0 | O12: =N12*$J12 -> 0 | Q12: =P12*$J12 -> 0 | S12: =R12*$J12 -> 0 | U12: =T12*$J12 -> 0 | W12: =V12*$J12 -> 0
E13: =SUM(B13:D13) -> 0 | G13: Concrete Sidwalk | M13: =L13*$J13 -> 0 | O13: =N13*$J13 -> 0 | Q13: =P13*$J13 -> 0 | S13: =R13*$J13 -> 0 | U13: =T13*$J13 -> 0 | W13: =V13*$J13 -> 0
E14: =SUM(B14:D14) -> 0 | G14: Building staking | M14: =L14*$J14 -> 0 | O14: =N14*$J14 -> 0 | Q14: =P14*$J14 -> 0 | S14: =R14*$J14 -> 0 | U14: =T14*$J14 -> 0 | W14: =V14*$J14 -> 0
E15: =SUM(B15:D15) -> 0 | G15: Grid lines | M15: =L15*$J15 -> 0 | O15: =N15*$J15 -> 0 | Q15: =P15*$J15 -> 0 | S15: =R15*$J15 -> 0 | U15: =T15*$J15 -> 0 | W15: =V15*$J15 -> 0
E16: =SUM(B16:D16) -> 0 | G16: Piles | M16: =L16*$J16 -> 0 | O16: =N16*$J16 -> 0 | Q16: =P16*$J16 -> 0 | S16: =R16*$J16 -> 0 | U16: =T16*$J16 -> 0 | W16: =V16*$J16 -> 0
E17: =SUM(B17:D17) -> 0 | M17: =L17*$J17 -> 0 | O17: =N17*$J17 -> 0 | Q17: =P17*$J17 -> 0 | S17: =R17*$J17 -> 0 | U17: =T17*$J17 -> 0 | W17: =V17*$J17 -> 0
E18: =SUM(B18:D18) -> 0 | M18: =L18*$J18 -> 0 | O18: =N18*$J18 -> 0 | Q18: =P18*$J18 -> 0 | S18: =R18*$J18 -> 0 | U18: =T18*$J18 -> 0 | W18: =V18*$J18 -> 0
E19: =SUM(B19:D19) -> 0 | M19: =L19*$J19 -> 0 | O19: =N19*$J19 -> 0 | Q19: =P19*$J19 -> 0 | S19: =R19*$J19 -> 0 | U19: =T19*$J19 -> 0 | W19: =V19*$J19 -> 0
E20: =SUM(B20:D20) -> 0 | M20: =L20*$J20 -> 0 | O20: =N20*$J20 -> 0 | Q20: =P20*$J20 -> 0 | S20: =R20*$J20 -> 0 | U20: =T20*$J20 -> 0 | W20: =V20*$J20 -> 0
E21: =SUM(B21:D21) -> 0 | M21: =L21*$J21 -> 0 | O21: =N21*$J21 -> 0 | Q21: =P21*$J21 -> 0 | S21: =R21*$J21 -> 0 | U21: =T21*$J21 -> 0 | W21: =V21*$J21 -> 0
E22: =SUM(B22:D22) -> 0 | M22: =L22*$J22 -> 0 | O22: =N22*$J22 -> 0 | Q22: =P22*$J22 -> 0 | S22: =R22*$J22 -> 0 | U22: =T22*$J22 -> 0 | W22: =V22*$J22 -> 0
E23: =SUM(B23:D23) -> 0 | M23: =L23*$J23 -> 0 | O23: =N23*$J23 -> 0 | Q23: =P23*$J23 -> 0 | S23: =R23*$J23 -> 0 | U23: =T23*$J23 -> 0 | W23: =V23*$J23 -> 0
E24: =SUM(B24:D24) -> 0 | M24: =L24*$J24 -> 0 | O24: =N24*$J24 -> 0 | Q24: =P24*$J24 -> 0 | S24: =R24*$J24 -> 0 | U24: =T24*$J24 -> 0 | W24: =V24*$J24 -> 0
E25: =SUM(B25:D25) -> 0 | M25: =L25*$J25 -> 0 | O25: =N25*$J25 -> 0 | Q25: =P25*$J25 -> 0 | S25: =R25*$J25 -> 0 | U25: =T25*$J25 -> 0 | W25: =V25*$J25 -> 0
E26: =SUM(B26:D26) -> 0 | M26: =L26*$J26 -> 0 | O26: =N26*$J26 -> 0 | Q26: =P26*$J26 -> 0 | S26: =R26*$J26 -> 0 | U26: =T26*$J26 -> 0 | W26: =V26*$J26 -> 0
E27: =SUM(B27:D27) -> 0 | M27: =L27*$J27 -> 0 | O27: =N27*$J27 -> 0 | Q27: =P27*$J27 -> 0 | S27: =R27*$J27 -> 0 | U27: =T27*$J27 -> 0 | W27: =V27*$J27 -> 0
E28: =SUM(B28:D28) -> 0 | M28: =L28*$J28 -> 0 | O28: =N28*$J28 -> 0 | Q28: =P28*$J28 -> 0 | S28: =R28*$J28 -> 0 | U28: =T28*$J28 -> 0 | W28: =V28*$J28 -> 0
... E31: =SUM(B31:D31) -> 0 | M31: =L31*$J31 -> 0 | O31: =N31*$J31 -> 0 | Q31: =P31*$J31 -> 0 | S31: =R31*$J31 -> 0 | U31: =T31*$J31 -> 0 | W31: =V31*$J31 -> 0
B32: =SUM(B9:B31) -> 0 | C32: =SUM(C9:C31) -> 0 | D32: =SUM(D9:D31) -> 0 | E32: =SUM(E9:E31) -> 0 | G32: SUBTOTAL | M32: =SUM(M9:M31) -> 0 | O32: =SUM(O9:O31) -> 0 | Q32: =SUM(Q9:Q31) -> 0 | S32: =SUM(S9:S31) -> 0 | U32: =SUM(U9:U31) -> 0 | W32: =SUM(W9:W31) -> 0
G33: TAX RATE % | M33: =$C$41 -> 0 | O33: =$C$41 -> 0 | Q33: =$C$41 -> 0 | S33: =$C$41 -> 0 | U33: =$C$41 -> 0 | W33: =$C$41 -> 0
G34: TOTAL TAX | M34: =M32*M33 -> 0 | O34: =O32*O33 -> 0 | Q34: =Q32*Q33 -> 0 | S34: =S32*S33 -> 0 | U34: =U32*U33 -> 0 | W34: =W32*W33 -> 0
B35: =B32 -> 0 | C35: =C32 -> 0 | D35: =D32 -> 0 | E35: =SUM(E32) -> 0 | G35: GRAND TOTAL | M35: =SUM(M32,M34) -> 0 | O35: =SUM(O32,O34) -> 0 | Q35: =SUM(Q32,Q34) -> 0 | S35: =SUM(S32,S34) -> 0 | U35: =SUM(U32,U34) -> 0 | W35: =SUM(W32,W34) -> 0
G36: BUDGET - OVER/(UNDER) | M36: =M35-$E$35 -> 0 | O36: =O35-$E$35 -> 0 | Q36: =Q35-$E$35 -> 0 | S36: =S35-$E$35 -> 0 | U36: =U35-$E$35 -> 0 | W36: =W35-$E$35 -> 0
G37: BUDGET - OVER/(UNDER) % | M37: =M36 / $E$35 -> #DIV/0! | O37: =O36 / $E$35 -> #DIV/0! | Q37: =Q36 / $E$35 -> #DIV/0! | S37: =S36 / $E$35 -> #DIV/0! | U37: =U36 / $E$35 -> #DIV/0! | W37: =W36 / $E$35 -> #DIV/0!
B41: TAX RATE | C41: 0

Sheet 03-3000 Concrete
B1: INDEX
B2: TYPE OF WORK: | D2: {=MID(CELL("filename", A1), FIND("]", CELL("filename", A1)) + 1, 255)} -> #VALUE! | J2: VENDOR NUMBER | L2: 1 | N2: 2 | P2: 3 | R2: 4 | T2: 5 | V2: 6
B3: PROJECT NAME: | D3: ='Project Info'!D4 -> NAME | J3: NAME:
B4: PROJECT DATE: | D4: ='Project Info'!D5 -> DATE | J4: CONTACT:
J5: PHONE:
J6: EMAIL:
B7: BUDGET: | J7: DATE:
B8: LABOR | C8: MATERIAL | D8: SUB | E8: TOTAL | F8: COST CODE | G8: ITEM DESCRIPTION | J8: QUANTITY | K8: UNIT | L8: PRICE | M8: TOTAL | N8: PRICE | O8: TOTAL | P8: PRICE | Q8: TOTAL | R8: PRICE | S8: TOTAL | T8: PRICE | U8: TOTAL | V8: PRICE | W8: TOTAL
C9: LOW | D9: {=MIN(IF(M35:W35>0, M35:W35))} -> 0 | E9: =SUM(B9:D9) -> 0 | F9: 03-3000 | G9: Concrete | M9: =L9*$J9 -> 0 | O9: =N9*$J9 -> 0 | Q9: =P9*$J9 -> 0 | S9: =R9*$J9 -> 0 | U9: =T9*$J9 -> 0 | W9: =V9*$J9 -> 0
E10: =SUM(B10:D10) -> 0 | M10: =L10*$J10 -> 0 | O10: =N10*$J10 -> 0 | Q10: =P10*$J10 -> 0 | S10: =R10*$J10 -> 0 | U10: =T10*$J10 -> 0 | W10: =V10*$J10 -> 0
E11: =SUM(B11:D11) -> 0 | G11: SOG | H11: SOG | I11: SOG | M11: =L11*$J11 -> 0 | O11: =N11*$J11 -> 0 | Q11: =P11*$J11 -> 0 | S11: =R11*$J11 -> 0 | U11: =T11*$J11 -> 0 | W11: =V11*$J11 -> 0
E12: =SUM(B12:D12) -> 0 | G12: Stoops | H12: Stoops | I12: Stoops | M12: =L12*$J12 -> 0 | O12: =N12*$J12 -> 0 | Q12: =P12*$J12 -> 0 | S12: =R12*$J12 -> 0 | U12: =T12*$J12 -> 0 | W12: =V12*$J12 -> 0
E13: =SUM(B13:D13) -> 0 | G13: Concrete piers at pads for winter | H13: Concrete piers at pads for winter | I13: Concrete piers at pads for winter | M13: =L13*$J13 -> 0 | O13: =N13*$J13 -> 0 | Q13: =P13*$J13 -> 0 | S13: =R13*$J13 -> 0 | U13: =T13*$J13 -> 0 | W13: =V13*$J13 -> 0
E14: =SUM(B14:D14) -> 0 | G14: Amenity deck sloping slab | H14: Amenity deck sloping slab | I14: Amenity deck sloping slab | M14: =L14*$J14 -> 0 | O14: =N14*$J14 -> 0 | Q14: =P14*$J14 -> 0 | S14: =R14*$J14 -> 0 | U14: =T14*$J14 -> 0 | W14: =V14*$J14 -> 0
E15: =SUM(B15:D15) -> 0 | G15: Amenity deck topping slab | H15: Amenity deck topping slab | I15: Amenity deck topping slab | M15: =L15*$J15 -> 0 | O15: =N15*$J15 -> 0 | Q15: =P15*$J15 -> 0 | S15: =R15*$J15 -> 0 | U15: =T15*$J15 -> 0 | W15: =V15*$J15 -> 0
E16: =SUM(B16:D16) -> 0 | G16: Insulation at amenity deck (6" by others) | H16: Insulation at amenity deck (6" by others) | I16: Insulation at amenity deck (6" by others) | M16: =L16*$J16 -> 0 | O16: =N16*$J16 -> 0 | Q16: =P16*$J16 -> 0 | S16: =R16*$J16 -> 0 | U16: =T16*$J16 -> 0 | W16: =V16*$J16 -> 0
E17: =SUM(B17:D17) -> 0 | G17: Built up slabs including insulation | H17: Built up slabs including insulation | I17: Built up slabs including insulation | M17: =L17*$J17 -> 0 | O17: =N17*$J17 -> 0 | Q17: =P17*$J17 -> 0 | S17: =R17*$J17 -> 0 | U17: =T17*$J17 -> 0 | W17: =V17*$J17 -> 0
E18: =SUM(B18:D18) -> 0 | G18: Concrete filled pan stairs | H18: Concrete filled pan stairs | I18: Concrete filled pan stairs | M18: =L18*$J18 -> 0 | O18: =N18*$J18 -> 0 | Q18: =P18*$J18 -> 0 | S18: =R18*$J18 -> 0 | U18: =T18*$J18 -> 0 | W18: =V18*$J18 -> 0
E19: =SUM(B19:D19) -> 0 | M19: =L19*$J19 -> 0 | O19: =N19*$J19 -> 0 | Q19: =P19*$J19 -> 0 | S19: =R19*$J19 -> 0 | U19: =T19*$J19 -> 0 | W19: =V19*$J19 -> 0
E20: =SUM(B20:D20) -> 0 | G20: Precast topping - Average ????? | H20: Precast topping - Average ????? | I20: Precast topping - Average ????? | M20: =L20*$J20 -> 0 | O20: =N20*$J20 -> 0 | Q20: =P20*$J20 -> 0 | S20: =R20*$J20 -> 0 | U20: =T20*$J20 -> 0 | W20: =V20*$J20 -> 0
E21: =SUM(B21:D21) -> 0 | M21: =L21*$J21 -> 0 | O21: =N21*$J21 -> 0 | Q21: =P21*$J21 -> 0 | S21: =R21*$J21 -> 0 | U21: =T21*$J21 -> 0 | W21: =V21*$J21 -> 0
E22: =SUM(B22:D22) -> 0 | M22: =L22*$J22 -> 0 | O22: =N22*$J22 -> 0 | Q22: =P22*$J22 -> 0 | S22: =R22*$J22 -> 0 | U22: =T22*$J22 -> 0 | W22: =V22*$J22 -> 0
E23: =SUM(B23:D23) -> 0 | M23: =L23*$J23 -> 0 | O23: =N23*$J23 -> 0 | Q23: =P23*$J23 -> 0 | S23: =R23*$J23 -> 0 | U23: =T23*$J23 -> 0 | W23: =V23*$J23 -> 0
E24: =SUM(B24:D24) -> 0 | M24: =L24*$J24 -> 0 | O24: =N24*$J24 -> 0 | Q24: =P24*$J24 -> 0 | S24: =R24*$J24 -> 0 | U24: =T24*$J24 -> 0 | W24: =V24*$J24 -> 0
E25: =SUM(B25:D25) -> 0 | M25: =L25*$J25 -> 0 | O25: =N25*$J25 -> 0 | Q25: =P25*$J25 -> 0 | S25: =R25*$J25 -> 0 | U25: =T25*$J25 -> 0 | W25: =V25*$J25 -> 0
E26: =SUM(B26:D26) -> 0 | M26: =L26*$J26 -> 0 | O26: =N26*$J26 -> 0 | Q26: =P26*$J26 -> 0 | S26: =R26*$J26 -> 0 | U26: =T26*$J26 -> 0 | W26: =V26*$J26 -> 0
E27: =SUM(B27:D27) -> 0 | M27: =L27*$J27 -> 0 | O27: =N27*$J27 -> 0 | Q27: =P27*$J27 -> 0 | S27: =R27*$J27 -> 0 | U27: =T27*$J27 -> 0 | W27: =V27*$J27 -> 0
E28: =SUM(B28:D28) -> 0 | M28: =L28*$J28 -> 0 | O28: =N28*$J28 -> 0 | Q28: =P28*$J28 -> 0 | S28: =R28*$J28 -> 0 | U28: =T28*$J28 -> 0 | W28: =V28*$J28 -> 0
E29: =SUM(B29:D29) -> 0 | M29: =L29*$J29 -> 0 | O29: =N29*$J29 -> 0 | Q29: =P29*$J29 -> 0 | S29: =R29*$J29 -> 0 | U29: =T29*$J29 -> 0 | W29: =V29*$J29 -> 0
E30: =SUM(B30:D30) -> 0 | M30: =L30*$J30 -> 0 | O30: =N30*$J30 -> 0 | Q30: =P30*$J30 -> 0 | S30: =R30*$J30 -> 0 | U30: =T30*$J30 -> 0 | W30: =V30*$J30 -> 0
E31: =SUM(B31:D31) -> 0 | M31: =L31*$J31 -> 0 | O31: =N31*$J31 -> 0 | Q31: =P31*$J31 -> 0 | S31: =R31*$J31 -> 0 | U31: =T31*$J31 -> 0 | W31: =V31*$J31 -> 0
B32: =SUM(B9:B31) -> 0 | C32: =SUM(C9:C31) -> 0 | D32: =SUM(D9:D31) -> 0 | E32: =SUM(E9:E31) -> 0 | G32: SUBTOTAL | M32: =SUM(M9:M31) -> 0 | O32: =SUM(O9:O31) -> 0 | Q32: =SUM(Q9:Q31) -> 0 | S32: =SUM(S9:S31) -> 0 | U32: =SUM(U9:U31) -> 0 | W32: =SUM(W9:W31) -> 0
G33: TAX RATE % | M33: =$C$41 -> 0 | O33: =$C$41 -> 0 | Q33: =$C$41 -> 0 | S33: =$C$41 -> 0 | U33: =$C$41 -> 0 | W33: =$C$41 -> 0
G34: TOTAL TAX | M34: =M32*M33 -> 0 | O34: =O32*O33 -> 0 | Q34: =Q32*Q33 -> 0 | S34: =S32*S33 -> 0 | U34: =U32*U33 -> 0 | W34: =W32*W33 -> 0
B35: =B32 -> 0 | C35: =C32 -> 0 | D35: =D32 -> 0 | E35: =SUM(E32) -> 0 | G35: GRAND TOTAL | M35: =SUM(M32,M34) -> 0 | O35: =SUM(O32,O34) -> 0 | Q35: =SUM(Q32,Q34) -> 0 | S35: =SUM(S32,S34) -> 0 | U35: =SUM(U32,U34) -> 0 | W35: =SUM(W32,W34) -> 0
G36: BUDGET - OVER/(UNDER) | M36: =M35-$E$35 -> 0 | O36: =O35-$E$35 -> 0 | Q36: =Q35-$E$35 -> 0 | S36: =S35-$E$35 -> 0 | U36: =U35-$E$35 -> 0 | W36: =W35-$E$35 -> 0
G37: BUDGET - OVER/(UNDER) % | M37: =M36 / $E$35 -> #DIV/0! | O37: =O36 / $E$35 -> #DIV/0! | Q37: =Q36 / $E$35 -> #DIV/0! | S37: =S36 / $E$35 -> #DIV/0! | U37: =U36 / $E$35 -> #DIV/0! | W37: =W36 / $E$35 -> #DIV/0!
B41: TAX RATE | C41: 0

Sheet 03-4100 Precast Concrete
B1: INDEX
B2: TYPE OF WORK: | D2: {=MID(CELL("filename", A1), FIND("]", CELL("filename", A1)) + 1, 255)} -> #VALUE! | J2: VENDOR NUMBER | L2: 1 | N2: 2 | P2: 3 | R2: 4 | T2: 5 | V2: 6
B3: PROJECT NAME: | D3: ='Project Info'!D4 -> NAME | J3: NAME:
B4: PROJECT DATE: | D4: ='Project Info'!D5 -> DATE | J4: CONTACT:
J5: PHONE:
J6: EMAIL:
B7: BUDGET: | J7: DATE:
B8: LABOR | C8: MATERIAL | D8: SUB | E8: TOTAL | F8: COST CODE | G8: ITEM DESCRIPTION | J8: QUANTITY | K8: UNIT | L8: PRICE | M8: TOTAL | N8: PRICE | O8: TOTAL | P8: PRICE | Q8: TOTAL | R8: PRICE | S8: TOTAL | T8: PRICE | U8: TOTAL | V8: PRICE | W8: TOTAL
C9: LOW | D9: {=MIN(IF(M35:W35>0, M35:W35))} -> 0 | E9: =SUM(B9:D9) -> 0 | F9: 03-4100 | G9: Precast Concrete | M9: =L9*$J9 -> 0 | O9: =N9*$J9 -> 0 | Q9: =P9*$J9 -> 0 | S9: =R9*$J9 -> 0 | U9: =T9*$J9 -> 0 | W9: =V9*$J9 -> 0
E10: =SUM(B10:D10) -> 0 | M10: =L10*$J10 -> 0 | O10: =N10*$J10 -> 0 | Q10: =P10*$J10 -> 0 | S10: =R10*$J10 -> 0 | U10: =T10*$J10 -> 0 | W10: =V10*$J10 -> 0
E11: =SUM(B11:D11) -> 0 | G11: Plank | H11: Plank | I11: Plank | M11: =L11*$J11 -> 0 | O11: =N11*$J11 -> 0 | Q11: =P11*$J11 -> 0 | S11: =R11*$J11 -> 0 | U11: =T11*$J11 -> 0 | W11: =V11*$J11 -> 0
E12: =SUM(B12:D12) -> 0 | G12: Beams | H12: Beams | I12: Beams | M12: =L12*$J12 -> 0 | O12: =N12*$J12 -> 0 | Q12: =P12*$J12 -> 0 | S12: =R12*$J12 -> 0 | U12: =T12*$J12 -> 0 | W12: =V12*$J12 -> 0
E13: =SUM(B13:D13) -> 0 | G13: Columns | H13: Columns | I13: Columns | M13: =L13*$J13 -> 0 | O13: =N13*$J13 -> 0 | Q13: =P13*$J13 -> 0 | S13: =R13*$J13 -> 0 | U13: =T13*$J13 -> 0 | W13: =V13*$J13 -> 0
E14: =SUM(B14:D14) -> 0 | G14: Structural walls | H14: Structural walls | I14: Structural walls | M14: =L14*$J14 -> 0 | O14: =N14*$J14 -> 0 | Q14: =P14*$J14 -> 0 | S14: =R14*$J14 -> 0 | U14: =T14*$J14 -> 0 | W14: =V14*$J14 -> 0
E15: =SUM(B15:D15) -> 0 | G15: Steel clips | H15: Steel clips | I15: Steel clips | M15: =L15*$J15 -> 0 | O15: =N15*$J15 -> 0 | Q15: =P15*$J15 -> 0 | S15: =R15*$J15 -> 0 | U15: =T15*$J15 -> 0 | W15: =V15*$J15 -> 0
E16: =SUM(B16:D16) -> 0 | G16: Weeps | H16: Weeps | I16: Weeps | M16: =L16*$J16 -> 0 | O16: =N16*$J16 -> 0 | Q16: =P16*$J16 -> 0 | S16: =R16*$J16 -> 0 | U16: =T16*$J16 -> 0 | W16: =V16*$J16 -> 0
E17: =SUM(B17:D17) -> 0 | M17: =L17*$J17 -> 0 | O17: =N17*$J17 -> 0 | Q17: =P17*$J17 -> 0 | S17: =R17*$J17 -> 0 | U17: =T17*$J17 -> 0 | W17: =V17*$J17 -> 0
E18: =SUM(B18:D18) -> 0 | G18: Mobs | H18: Mobs | I18: Mobs | M18: =L18*$J18 -> 0 | O18: =N18*$J18 -> 0 | Q18: =P18*$J18 -> 0 | S18: =R18*$J18 -> 0 | U18: =T18*$J18 -> 0 | W18: =V18*$J18 -> 0
E19: =SUM(B19:D19) -> 0 | M19: =L19*$J19 -> 0 | O19: =N19*$J19 -> 0 | Q19: =P19*$J19 -> 0 | S19: =R19*$J19 -> 0 | U19: =T19*$J19 -> 0 | W19: =V19*$J19 -> 0
E20: =SUM(B20:D20) -> 0 | M20: =L20*$J20 -> 0 | O20: =N20*$J20 -> 0 | Q20: =P20*$J20 -> 0 | S20: =R20*$J20 -> 0 | U20: =T20*$J20 -> 0 | W20: =V20*$J20 -> 0
E21: =SUM(B21:D21) -> 0 | M21: =L21*$J21 -> 0 | O21: =N21*$J21 -> 0 | Q21: =P21*$J21 -> 0 | S21: =R21*$J21 -> 0 | U21: =T21*$J21 -> 0 | W21: =V21*$J21 -> 0
E22: =SUM(B22:D22) -> 0 | M22: =L22*$J22 -> 0 | O22: =N22*$J22 -> 0 | Q22: =P22*$J22 -> 0 | S22: =R22*$J22 -> 0 | U22: =T22*$J22 -> 0 | W22: =V22*$J22 -> 0
E23: =SUM(B23:D23) -> 0 | M23: =L23*$J23 -> 0 | O23: =N23*$J23 -> 0 | Q23: =P23*$J23 -> 0 | S23: =R23*$J23 -> 0 | U23: =T23*$J23 -> 0 | W23: =V23*$J23 -> 0
E24: =SUM(B24:D24) -> 0 | M24: =L24*$J24 -> 0 | O24: =N24*$J24 -> 0 | Q24: =P24*$J24 -> 0 | S24: =R24*$J24 -> 0 | U24: =T24*$J24 -> 0 | W24: =V24*$J24 -> 0
E25: =SUM(B25:D25) -> 0 | M25: =L25*$J25 -> 0 | O25: =N25*$J25 -> 0 | Q25: =P25*$J25 -> 0 | S25: =R25*$J25 -> 0 | U25: =T25*$J25 -> 0 | W25: =V25*$J25 -> 0
E26: =SUM(B26:D26) -> 0 | M26: =L26*$J26 -> 0 | O26: =N26*$J26 -> 0 | Q26: =P26*$J26 -> 0 | S26: =R26*$J26 -> 0 | U26: =T26*$J26 -> 0 | W26: =V26*$J26 -> 0
E27: =SUM(B27:D27) -> 0 | M27: =L27*$J27 -> 0 | O27: =N27*$J27 -> 0 | Q27: =P27*$J27 -> 0 | S27: =R27*$J27 -> 0 | U27: =T27*$J27 -> 0 | W27: =V27*$J27 -> 0
E28: =SUM(B28:D28) -> 0 | M28: =L28*$J28 -> 0 | O28: =N28*$J28 -> 0 | Q28: =P28*$J28 -> 0 | S28: =R28*$J28 -> 0 | U28: =T28*$J28 -> 0 | W28: =V28*$J28 -> 0
E29: =SUM(B29:D29) -> 0 | M29: =L29*$J29 -> 0 | O29: =N29*$J29 -> 0 | Q29: =P29*$J29 -> 0 | S29: =R29*$J29 -> 0 | U29: =T29*$J29 -> 0 | W29: =V29*$J29 -> 0
E30: =SUM(B30:D30) -> 0 | M30: =L30*$J30 -> 0 | O30: =N30*$J30 -> 0 | Q30: =P30*$J30 -> 0 | S30: =R30*$J30 -> 0 | U30: =T30*$J30 -> 0 | W30: =V30*$J30 -> 0
E31: =SUM(B31:D31) -> 0 | M31: =L31*$J31 -> 0 | O31: =N31*$J31 -> 0 | Q31: =P31*$J31 -> 0 | S31: =R31*$J31 -> 0 | U31: =T31*$J31 -> 0 | W31: =V31*$J31 -> 0
B32: =SUM(B9:B31) -> 0 | C32: =SUM(C9:C31) -> 0 | D32: =SUM(D9:D31) -> 0 | E32: =SUM(E9:E31) -> 0 | G32: SUBTOTAL | M32: =SUM(M9:M31) -> 0 | O32: =SUM(O9:O31) -> 0 | Q32: =SUM(Q9:Q31) -> 0 | S32: =SUM(S9:S31) -> 0 | U32: =SUM(U9:U31) -> 0 | W32: =SUM(W9:W31) -> 0
G33: TAX RATE % | M33: =$C$41 -> 0 | O33: =$C$41 -> 0 | Q33: =$C$41 -> 0 | S33: =$C$41 -> 0 | U33: =$C$41 -> 0 | W33: =$C$41 -> 0
G34: TOTAL TAX | M34: =M32*M33 -> 0 | O34: =O32*O33 -> 0 | Q34: =Q32*Q33 -> 0 | S34: =S32*S33 -> 0 | U34: =U32*U33 -> 0 | W34: =W32*W33 -> 0
B35: =B32 -> 0 | C35: =C32 -> 0 | D35: =D32 -> 0 | E35: =SUM(E32) -> 0 | G35: GRAND TOTAL | M35: =SUM(M32,M34) -> 0 | O35: =SUM(O32,O34) -> 0 | Q35: =SUM(Q32,Q34) -> 0 | S35: =SUM(S32,S34) -> 0 | U35: =SUM(U32,U34) -> 0 | W35: =SUM(W32,W34) -> 0
G36: BUDGET - OVER/(UNDER) | M36: =M35-$E$35 -> 0 | O36: =O35-$E$35 -> 0 | Q36: =Q35-$E$35 -> 0 | S36: =S35-$E$35 -> 0 | U36: =U35-$E$35 -> 0 | W36: =W35-$E$35 -> 0
G37: BUDGET - OVER/(UNDER) % | M37: =M36 / $E$35 -> #DIV/0! | O37: =O36 / $E$35 -> #DIV/0! | Q37: =Q36 / $E$35 -> #DIV/0! | S37: =S36 / $E$35 -> #DIV/0! | U37: =U36 / $E$35 -> #DIV/0! | W37: =W36 / $E$35 -> #DIV/0!
B41: TAX RATE | C41: 0

Sheet 03-5413 Gypcrete
B1: INDEX
B2: TYPE OF WORK: | D2: {=MID(CELL("filename", A1), FIND("]", CELL("filename", A1)) + 1, 255)} -> #VALUE! | J2: VENDOR NUMBER | L2: 1 | N2: 2 | P2: 3 | R2: 4 | T2: 5 | V2: 6
B3: PROJECT NAME: | D3: ='Project Info'!D4 -> NAME | J3: NAME:
B4: PROJECT DATE: | D4: ='Project Info'!D5 -> DATE | J4: CONTACT:
J5: PHONE:
J6: EMAIL:
B7: BUDGET: | J7: DATE:
B8: LABOR | C8: MATERIAL | D8: SUB | E8: TOTAL | F8: COST CODE | G8: ITEM DESCRIPTION | J8: QUANTITY | K8: UNIT | L8: PRICE | M8: TOTAL | N8: PRICE | O8: TOTAL | P8: PRICE | Q8: TOTAL | R8: PRICE | S8: TOTAL | T8: PRICE | U8: TOTAL | V8: PRICE | W8: TOTAL
C9: LOW | D9: {=MIN(IF(M35:W35>0, M35:W35))} -> 0 | E9: =SUM(B9:D9) -> 0 | F9: 03-5413 | G9: Gypcrete | M9: =L9*$J9 -> 0 | O9: =N9*$J9 -> 0 | Q9: =P9*$J9 -> 0 | S9: =R9*$J9 -> 0 | U9: =T9*$J9 -> 0 | W9: =V9*$J9 -> 0
E10: =SUM(B10:D10) -> 0 | G10: Wood | H10: Wood | I10: Wood | M10: =L10*$J10 -> 0 | O10: =N10*$J10 -> 0 | Q10: =P10*$J10 -> 0 | S10: =R10*$J10 -> 0 | U10: =T10*$J10 -> 0 | W10: =V10*$J10 -> 0
E11: =SUM(B11:D11) -> 0 | G11: 3/8" soundmat at hard and soft surfaces | H11: 3/8" soundmat at hard and soft surfaces | I11: 3/8" soundmat at hard and soft surfaces | M11: =L11*$J11 -> 0 | O11: =N11*$J11 -> 0 | Q11: =P11*$J11 -> 0 | S11: =R11*$J11 -> 0 | U11: =T11*$J11 -> 0 | W11: =V11*$J11 -> 0
E12: =SUM(B12:D12) -> 0 | G12: 1" gypcrete | H12: 1" gypcrete | I12: 1" gypcrete | M12: =L12*$J12 -> 0 | O12: =N12*$J12 -> 0 | Q12: =P12*$J12 -> 0 | S12: =R12*$J12 -> 0 | U12: =T12*$J12 -> 0 | W12: =V12*$J12 -> 0
E13: =SUM(B13:D13) -> 0 | G13: Precast - 1-3/8" Gyp | H13: Precast - 1-3/8" Gyp | I13: Precast - 1-3/8" Gyp | M13: =L13*$J13 -> 0 | O13: =N13*$J13 -> 0 | Q13: =P13*$J13 -> 0 | S13: =R13*$J13 -> 0 | U13: =T13*$J13 -> 0 | W13: =V13*$J13 -> 0
E14: =SUM(B14:D14) -> 0 | G14: 1-3/8" gypcrete on precast | H14: 1-3/8" gypcrete on precast | I14: 1-3/8" gypcrete on precast | M14: =L14*$J14 -> 0 | O14: =N14*$J14 -> 0 | Q14: =P14*$J14 -> 0 | S14: =R14*$J14 -> 0 | U14: =T14*$J14 -> 0 | W14: =V14*$J14 -> 0
E15: =SUM(B15:D15) -> 0 | G15: 2500 PSI in units | H15: 2500 PSI in units | I15: 2500 PSI in units | M15: =L15*$J15 -> 0 | O15: =N15*$J15 -> 0 | Q15: =P15*$J15 -> 0 | S15: =R15*$J15 -> 0 | U15: =T15*$J15 -> 0 | W15: =V15*$J15 -> 0
E16: =SUM(B16:D16) -> 0 | G16: 3000 PSI in corridors | H16: 3000 PSI in corridors | I16: 3000 PSI in corridors | M16: =L16*$J16 -> 0 | O16: =N16*$J16 -> 0 | Q16: =P16*$J16 -> 0 | S16: =R16*$J16 -> 0 | U16: =T16*$J16 -> 0 | W16: =V16*$J16 -> 0
E17: =SUM(B17:D17) -> 0 | M17: =L17*$J17 -> 0 | O17: =N17*$J17 -> 0 | Q17: =P17*$J17 -> 0 | S17: =R17*$J17 -> 0 | U17: =T17*$J17 -> 0 | W17: =V17*$J17 -> 0
E18: =SUM(B18:D18) -> 0 | G18: Mobs | H18: Mobs | I18: Mobs | M18: =L18*$J18 -> 0 | O18: =N18*$J18 -> 0 | Q18: =P18*$J18 -> 0 | S18: =R18*$J18 -> 0 | U18: =T18*$J18 -> 0 | W18: =V18*$J18 -> 0
E19: =SUM(B19:D19) -> 0 | M19: =L19*$J19 -> 0 | O19: =N19*$J19 -> 0 | Q19: =P19*$J19 -> 0 | S19: =R19*$J19 -> 0 | U19: =T19*$J19 -> 0 | W19: =V19*$J19 -> 0
E20: =SUM(B20:D20) -> 0 | G20: Deduct - no soundmat in carpeted areas | H20: Deduct - no soundmat in carpeted areas | I20: Deduct - no soundmat in carpeted areas | M20: =L20*$J20 -> 0 | O20: =N20*$J20 -> 0 | Q20: =P20*$J20 -> 0 | S20: =R20*$J20 -> 0 | U20: =T20*$J20 -> 0 | W20: =V20*$J20 -> 0
E21: =SUM(B21:D21) -> 0 | M21: =L21*$J21 -> 0 | O21: =N21*$J21 -> 0 | Q21: =P21*$J21 -> 0 | S21: =R21*$J21 -> 0 | U21: =T21*$J21 -> 0 | W21: =V21*$J21 -> 0
E22: =SUM(B22:D22) -> 0 | M22: =L22*$J22 -> 0 | O22: =N22*$J22 -> 0 | Q22: =P22*$J22 -> 0 | S22: =R22*$J22 -> 0 | U22: =T22*$J22 -> 0 | W22: =V22*$J22 -> 0
E23: =SUM(B23:D23) -> 0 | M23: =L23*$J23 -> 0 | O23: =N23*$J23 -> 0 | Q23: =P23*$J23 -> 0 | S23: =R23*$J23 -> 0 | U23: =T23*$J23 -> 0 | W23: =V23*$J23 -> 0
E24: =SUM(B24:D24) -> 0 | M24: =L24*$J24 -> 0 | O24: =N24*$J24 -> 0 | Q24: =P24*$J24 -> 0 | S24: =R24*$J24 -> 0 | U24: =T24*$J24 -> 0 | W24: =V24*$J24 -> 0
E25: =SUM(B25:D25) -> 0 | M25: =L25*$J25 -> 0 | O25: =N25*$J25 -> 0 | Q25: =P25*$J25 -> 0 | S25: =R25*$J25 -> 0 | U25: =T25*$J25 -> 0 | W25: =V25*$J25 -> 0
E26: =SUM(B26:D26) -> 0 | M26: =L26*$J26 -> 0 | O26: =N26*$J26 -> 0 | Q26: =P26*$J26 -> 0 | S26: =R26*$J26 -> 0 | U26: =T26*$J26 -> 0 | W26: =V26*$J26 -> 0
E27: =SUM(B27:D27) -> 0 | M27: =L27*$J27 -> 0 | O27: =N27*$J27 -> 0 | Q27: =P27*$J27 -> 0 | S27: =R27*$J27 -> 0 | U27: =T27*$J27 -> 0 | W27: =V27*$J27 -> 0
E28: =SUM(B28:D28) -> 0 | M28: =L28*$J28 -> 0 | O28: =N28*$J28 -> 0 | Q28: =P28*$J28 -> 0 | S28: =R28*$J28 -> 0 | U28: =T28*$J28 -> 0 | W28: =V28*$J28 -> 0
E29: =SUM(B29:D29) -> 0 | M29: =L29*$J29 -> 0 | O29: =N29*$J29 -> 0 | Q29: =P29*$J29 -> 0 | S29: =R29*$J29 -> 0 | U29: =T29*$J29 -> 0 | W29: =V29*$J29 -> 0
E30: =SUM(B30:D30) -> 0 | M30: =L30*$J30 -> 0 | O30: =N30*$J30 -> 0 | Q30: =P30*$J30 -> 0 | S30: =R30*$J30 -> 0 | U30: =T30*$J30 -> 0 | W30: =V30*$J30 -> 0
E31: =SUM(B31:D31) -> 0 | M31: =L31*$J31 -> 0 | O31: =N31*$J31 -> 0 | Q31: =P31*$J31 -> 0 | S31: =R31*$J31 -> 0 | U31: =T31*$J31 -> 0 | W31: =V31*$J31 -> 0
B32: =SUM(B9:B31) -> 0 | C32: =SUM(C9:C31) -> 0 | D32: =SUM(D9:D31) -> 0 | E32: =SUM(E9:E31) -> 0 | G32: SUBTOTAL | M32: =SUM(M9:M31) -> 0 | O32: =SUM(O9:O31) -> 0 | Q32: =SUM(Q9:Q31) -> 0 | S32: =SUM(S9:S31) -> 0 | U32: =SUM(U9:U31) -> 0 | W32: =SUM(W9:W31) -> 0
G33: TAX RATE % | M33: =$C$41 -> 0 | O33: =$C$41 -> 0 | Q33: =$C$41 -> 0 | S33: =$C$41 -> 0 | U33: =$C$41 -> 0 | W33: =$C$41 -> 0
G34: TOTAL TAX | M34: =M32*M33 -> 0 | O34: =O32*O33 -> 0 | Q34: =Q32*Q33 -> 0 | S34: =S32*S33 -> 0 | U34: =U32*U33 -> 0 | W34: =W32*W33 -> 0
B35: =B32 -> 0 | C35: =C32 -> 0 | D35: =D32 -> 0 | E35: =SUM(E32) -> 0 | G35: GRAND TOTAL | M35: =SUM(M32,M34) -> 0 | O35: =SUM(O32,O34) -> 0 | Q35: =SUM(Q32,Q34) -> 0 | S35: =SUM(S32,S34) -> 0 | U35: =SUM(U32,U34) -> 0 | W35: =SUM(W32,W34) -> 0
G36: BUDGET - OVER/(UNDER) | M36: =M35-$E$35 -> 0 | O36: =O35-$E$35 -> 0 | Q36: =Q35-$E$35 -> 0 | S36: =S35-$E$35 -> 0 | U36: =U35-$E$35 -> 0 | W36: =W35-$E$35 -> 0
G37: BUDGET - OVER/(UNDER) % | M37: =M36 / $E$35 -> #DIV/0! | O37: =O36 / $E$35 -> #DIV/0! | Q37: =Q36 / $E$35 -> #DIV/0! | S37: =S36 / $E$35 -> #DIV/0! | U37: =U36 / $E$35 -> #DIV/0! | W37: =W36 / $E$35 -> #DIV/0!
B41: TAX RATE | C41: 0

Sheet 04-0000 Masonry
B1: INDEX
B2: TYPE OF WORK: | D2: {=MID(CELL("filename", A1), FIND("]", CELL("filename", A1)) + 1, 255)} -> #VALUE! | J2: VENDOR NUMBER | L2: 1 | N2: 2 | P2: 3 | R2: 4 | T2: 5 | V2: 6
B3: PROJECT NAME: | D3: ='Project Info'!D4 -> NAME | J3: NAME:
B4: PROJECT DATE: | D4: ='Project Info'!D5 -> DATE | J4: CONTACT:
J5: PHONE:
J6: EMAIL:
B7: BUDGET: | J7: DATE:
B8: LABOR | C8: MATERIAL | D8: SUB | E8: TOTAL | F8: COST CODE | G8: ITEM DESCRIPTION | J8: QUANTITY | K8: UNIT | L8: PRICE | M8: TOTAL | N8: PRICE | O8: TOTAL | P8: PRICE | Q8: TOTAL | R8: PRICE | S8: TOTAL | T8: PRICE | U8: TOTAL | V8: PRICE | W8: TOTAL
C9: LOW | D9: {=MIN(IF(M35:W35>0, M35:W35))} -> 0 | E9: =SUM(B9:D9) -> 0 | F9: 04-0000 | G9: MASONRY | M9: =L9*$J9 -> 0 | O9: =N9*$J9 -> 0 | Q9: =P9*$J9 -> 0 | S9: =R9*$J9 -> 0 | U9: =T9*$J9 -> 0 | W9: =V9*$J9 -> 0
E10: =SUM(B10:D10) -> 0 | M10: =L10*$J10 -> 0 | O10: =N10*$J10 -> 0 | Q10: =P10*$J10 -> 0 | S10: =R10*$J10 -> 0 | U10: =T10*$J10 -> 0 | W10: =V10*$J10 -> 0
E11: =SUM(B11:D11) -> 0 | G11: CMU foundations walls | H11: CMU foundations walls | I11: CMU foundations walls | M11: =L11*$J11 -> 0 | O11: =N11*$J11 -> 0 | Q11: =P11*$J11 -> 0 | S11: =R11*$J11 -> 0 | U11: =T11*$J11 -> 0 | W11: =V11*$J11 -> 0
E12: =SUM(B12:D12) -> 0 | G12: Interior CMU walls | H12: Interior CMU walls | I12: Interior CMU walls | M12: =L12*$J12 -> 0 | O12: =N12*$J12 -> 0 | Q12: =P12*$J12 -> 0 | S12: =R12*$J12 -> 0 | U12: =T12*$J12 -> 0 | W12: =V12*$J12 -> 0
E13: =SUM(B13:D13) -> 0 | G13: Structural walls (on struct) | H13: Structural walls (on struct) | I13: Structural walls (on struct) | M13: =L13*$J13 -> 0 | O13: =N13*$J13 -> 0 | Q13: =P13*$J13 -> 0 | S13: =R13*$J13 -> 0 | U13: =T13*$J13 -> 0 | W13: =V13*$J13 -> 0
E14: =SUM(B14:D14) -> 0 | G14: Architectural walls (on arch) | H14: Architectural walls (on arch) | I14: Architectural walls (on arch) | M14: =L14*$J14 -> 0 | O14: =N14*$J14 -> 0 | Q14: =P14*$J14 -> 0 | S14: =R14*$J14 -> 0 | U14: =T14*$J14 -> 0 | W14: =V14*$J14 -> 0
E15: =SUM(B15:D15) -> 0 | M15: =L15*$J15 -> 0 | O15: =N15*$J15 -> 0 | Q15: =P15*$J15 -> 0 | S15: =R15*$J15 -> 0 | U15: =T15*$J15 -> 0 | W15: =V15*$J15 -> 0
E16: =SUM(B16:D16) -> 0 | G16: Brick/stone veneer | H16: Brick/stone veneer | I16: Brick/stone veneer | M16: =L16*$J16 -> 0 | O16: =N16*$J16 -> 0 | Q16: =P16*$J16 -> 0 | S16: =R16*$J16 -> 0 | U16: =T16*$J16 -> 0 | W16: =V16*$J16 -> 0
E17: =SUM(B17:D17) -> 0 | G17: Block back-up | H17: Block back-up | I17: Block back-up | M17: =L17*$J17 -> 0 | O17: =N17*$J17 -> 0 | Q17: =P17*$J17 -> 0 | S17: =R17*$J17 -> 0 | U17: =T17*$J17 -> 0 | W17: =V17*$J17 -> 0
E18: =SUM(B18:D18) -> 0 | M18: =L18*$J18 -> 0 | O18: =N18*$J18 -> 0 | Q18: =P18*$J18 -> 0 | S18: =R18*$J18 -> 0 | U18: =T18*$J18 -> 0 | W18: =V18*$J18 -> 0
E19: =SUM(B19:D19) -> 0 | G19: Rigid insulation behind brick | H19: Rigid insulation behind brick | I19: Rigid insulation behind brick | M19: =L19*$J19 -> 0 | O19: =N19*$J19 -> 0 | Q19: =P19*$J19 -> 0 | S19: =R19*$J19 -> 0 | U19: =T19*$J19 -> 0 | W19: =V19*$J19 -> 0
E20: =SUM(B20:D20) -> 0 | M20: =L20*$J20 -> 0 | O20: =N20*$J20 -> 0 | Q20: =P20*$J20 -> 0 | S20: =R20*$J20 -> 0 | U20: =T20*$J20 -> 0 | W20: =V20*$J20 -> 0
E21: =SUM(B21:D21) -> 0 | M21: =L21*$J21 -> 0 | O21: =N21*$J21 -> 0 | Q21: =P21*$J21 -> 0 | S21: =R21*$J21 -> 0 | U21: =T21*$J21 -> 0 | W21: =V21*$J21 -> 0
E22: =SUM(B22:D22) -> 0 | M22: =L22*$J22 -> 0 | O22: =N22*$J22 -> 0 | Q22: =P22*$J22 -> 0 | S22: =R22*$J22 -> 0 | U22: =T22*$J22 -> 0 | W22: =V22*$J22 -> 0
E23: =SUM(B23:D23) -> 0 | M23: =L23*$J23 -> 0 | O23: =N23*$J23 -> 0 | Q23: =P23*$J23 -> 0 | S23: =R23*$J23 -> 0 | U23: =T23*$J23 -> 0 | W23: =V23*$J23 -> 0
E24: =SUM(B24:D24) -> 0 | M24: =L24*$J24 -> 0 | O24: =N24*$J24 -> 0 | Q24: =P24*$J24 -> 0 | S24: =R24*$J24 -> 0 | U24: =T24*$J24 -> 0 | W24: =V24*$J24 -> 0
E25: =SUM(B25:D25) -> 0 | M25: =L25*$J25 -> 0 | O25: =N25*$J25 -> 0 | Q25: =P25*$J25 -> 0 | S25: =R25*$J25 -> 0 | U25: =T25*$J25 -> 0 | W25: =V25*$J25 -> 0
E26: =SUM(B26:D26) -> 0 | M26: =L26*$J26 -> 0 | O26: =N26*$J26 -> 0 | Q26: =P26*$J26 -> 0 | S26: =R26*$J26 -> 0 | U26: =T26*$J26 -> 0 | W26: =V26*$J26 -> 0
E27: =SUM(B27:D27) -> 0 | M27: =L27*$J27 -> 0 | O27: =N27*$J27 -> 0 | Q27: =P27*$J27 -> 0 | S27: =R27*$J27 -> 0 | U27: =T27*$J27 -> 0 | W27: =V27*$J27 -> 0
E28: =SUM(B28:D28) -> 0 | M28: =L28*$J28 -> 0 | O28: =N28*$J28 -> 0 | Q28: =P28*$J28 -> 0 | S28: =R28*$J28 -> 0 | U28: =T28*$J28 -> 0 | W28: =V28*$J28 -> 0
E29: =SUM(B29:D29) -> 0 | M29: =L29*$J29 -> 0 | O29: =N29*$J29 -> 0 | Q29: =P29*$J29 -> 0 | S29: =R29*$J29 -> 0 | U29: =T29*$J29 -> 0 | W29: =V29*$J29 -> 0
E30: =SUM(B30:D30) -> 0 | M30: =L30*$J30 -> 0 | O30: =N30*$J30 -> 0 | Q30: =P30*$J30 -> 0 | S30: =R30*$J30 -> 0 | U30: =T30*$J30 -> 0 | W30: =V30*$J30 -> 0
E31: =SUM(B31:D31) -> 0 | M31: =L31*$J31 -> 0 | O31: =N31*$J31 -> 0 | Q31: =P31*$J31 -> 0 | S31: =R31*$J31 -> 0 | U31: =T31*$J31 -> 0 | W31: =V31*$J31 -> 0
B32: =SUM(B9:B31) -> 0 | C32: =SUM(C9:C31) -> 0 | D32: =SUM(D9:D31) -> 0 | E32: =SUM(E9:E31) -> 0 | G32: SUBTOTAL | M32: =SUM(M9:M31) -> 0 | O32: =SUM(O9:O31) -> 0 | Q32: =SUM(Q9:Q31) -> 0 | S32: =SUM(S9:S31) -> 0 | U32: =SUM(U9:U31) -> 0 | W32: =SUM(W9:W31) -> 0
G33: TAX RATE % | M33: =$C$41 -> 0 | O33: =$C$41 -> 0 | Q33: =$C$41 -> 0 | S33: =$C$41 -> 0 | U33: =$C$41 -> 0 | W33: =$C$41 -> 0
G34: TOTAL TAX | M34: =M32*M33 -> 0 | O34: =O32*O33 -> 0 | Q34: =Q32*Q33 -> 0 | S34: =S32*S33 -> 0 | U34: =U32*U33 -> 0 | W34: =W32*W33 -> 0
B35: =B32 -> 0 | C35: =C32 -> 0 | D35: =D32 -> 0 | E35: =SUM(E32) -> 0 | G35: GRAND TOTAL | M35: =SUM(M32,M34) -> 0 | O35: =SUM(O32,O34) -> 0 | Q35: =SUM(Q32,Q34) -> 0 | S35: =SUM(S32,S34) -> 0 | U35: =SUM(U32,U34) -> 0 | W35: =SUM(W32,W34) -> 0
G36: BUDGET - OVER/(UNDER) | M36: =M35-$E$35 -> 0 | O36: =O35-$E$35 -> 0 | Q36: =Q35-$E$35 -> 0 | S36: =S35-$E$35 -> 0 | U36: =U35-$E$35 -> 0 | W36: =W35-$E$35 -> 0
G37: BUDGET - OVER/(UNDER) % | M37: =M36 / $E$35 -> #DIV/0! | O37: =O36 / $E$35 -> #DIV/0! | Q37: =Q36 / $E$35 -> #DIV/0! | S37: =S36 / $E$35 -> #DIV/0! | U37: =U36 / $E$35 -> #DIV/0! | W37: =W36 / $E$35 -> #DIV/0!
B41: TAX RATE | C41: 0

Sheet 05-1200 Structural Steel
B1: INDEX
B2: TYPE OF WORK: | D2: {=MID(CELL("filename", A1), FIND("]", CELL("filename", A1)) + 1, 255)} -> #VALUE! | H2: Apparent Low: | J2: VENDOR NUMBER | L2: 1 | N2: 2 | P2: 3 | R2: 4 | T2: 5 | V2: 6
B3: PROJECT NAME: | D3: ='Project Info'!D4 -> NAME | H3: {=IF(MIN(IF(M34:W34>0, M34:W34, ""))="", "", INDEX(L3:V3, MATCH(MIN(IF(M34:W34>0, M34:W34, "")), IF(MOD(COLUMN(M34:W34)-COLUMN(M34)+1, 2)=1, M34:W34, ""), 0)))} -> 0 | J3: NAME:
B4: PROJECT DATE: | D4: ='Project Info'!D5 -> DATE | J4: CONTACT:
J5: PHONE:
J6: EMAIL:
B7: BUDGET: | J7: DATE:
B8: LABOR | C8: MATERIAL | D8: SUB | E8: TOTAL | F8: COST CODE | G8: ITEM DESCRIPTION | J8: QUANTITY | K8: UNIT | L8: PRICE | M8: TOTAL | N8: PRICE | O8: TOTAL | P8: PRICE | Q8: TOTAL | R8: PRICE | S8: TOTAL | T8: PRICE | U8: TOTAL | V8: PRICE | W8: TOTAL
C9: LOW | D9: {=MIN(IF(M35:W35>0, M35:W35))} -> 0 | E9: =SUM(B9:D9) -> 0 | F9: 05-1200 | G9: Structural Steel | M9: =L9*$J9 -> 0 | O9: =N9*$J9 -> 0 | Q9: =P9*$J9 -> 0 | S9: =R9*$J9 -> 0 | U9: =T9*$J9 -> 0 | W9: =V9*$J9 -> 0
E10: =SUM(B10:D10) -> 0 | M10: =L10*$J10 -> 0 | O10: =N10*$J10 -> 0 | Q10: =P10*$J10 -> 0 | S10: =R10*$J10 -> 0 | U10: =T10*$J10 -> 0 | W10: =V10*$J10 -> 0
E11: =SUM(B11:D11) -> 0 | G11: Installation | H11: Installation | I11: Installation | M11: =L11*$J11 -> 0 | O11: =N11*$J11 -> 0 | Q11: =P11*$J11 -> 0 | S11: =R11*$J11 -> 0 | U11: =T11*$J11 -> 0 | W11: =V11*$J11 -> 0
E12: =SUM(B12:D12) -> 0 | G12: CMU Clips | H12: CMU Clips | I12: CMU Clips | M12: =L12*$J12 -> 0 | O12: =N12*$J12 -> 0 | Q12: =P12*$J12 -> 0 | S12: =R12*$J12 -> 0 | U12: =T12*$J12 -> 0 | W12: =V12*$J12 -> 0
E13: =SUM(B13:D13) -> 0 | M13: =L13*$J13 -> 0 | O13: =N13*$J13 -> 0 | Q13: =P13*$J13 -> 0 | S13: =R13*$J13 -> 0 | U13: =T13*$J13 -> 0 | W13: =V13*$J13 -> 0
E14: =SUM(B14:D14) -> 0 | G14: Loose lintels - galvanized | H14: Loose lintels - galvanized | I14: Loose lintels - galvanized | M14: =L14*$J14 -> 0 | O14: =N14*$J14 -> 0 | Q14: =P14*$J14 -> 0 | S14: =R14*$J14 -> 0 | U14: =T14*$J14 -> 0 | W14: =V14*$J14 -> 0
E15: =SUM(B15:D15) -> 0 | M15: =L15*$J15 -> 0 | O15: =N15*$J15 -> 0 | Q15: =P15*$J15 -> 0 | S15: =R15*$J15 -> 0 | U15: =T15*$J15 -> 0 | W15: =V15*$J15 -> 0
E16: =SUM(B16:D16) -> 0 | G16: Steel stairs | H16: Steel stairs | I16: Steel stairs | M16: =L16*$J16 -> 0 | O16: =N16*$J16 -> 0 | Q16: =P16*$J16 -> 0 | S16: =R16*$J16 -> 0 | U16: =T16*$J16 -> 0 | W16: =V16*$J16 -> 0
E17: =SUM(B17:D17) -> 0 | G17: Steel railings | H17: Steel railings | I17: Steel railings | M17: =L17*$J17 -> 0 | O17: =N17*$J17 -> 0 | Q17: =P17*$J17 -> 0 | S17: =R17*$J17 -> 0 | U17: =T17*$J17 -> 0 | W17: =V17*$J17 -> 0
E18: =SUM(B18:D18) -> 0 | G18: Steel stairs podium down | H18: Steel stairs podium down | I18: Steel stairs podium down | M18: =L18*$J18 -> 0 | O18: =N18*$J18 -> 0 | Q18: =P18*$J18 -> 0 | S18: =R18*$J18 -> 0 | U18: =T18*$J18 -> 0 | W18: =V18*$J18 -> 0
E19: =SUM(B19:D19) -> 0 | G19: Elevator Beams | H19: Elevator Beams | I19: Elevator Beams | M19: =L19*$J19 -> 0 | O19: =N19*$J19 -> 0 | Q19: =P19*$J19 -> 0 | S19: =R19*$J19 -> 0 | U19: =T19*$J19 -> 0 | W19: =V19*$J19 -> 0
E20: =SUM(B20:D20) -> 0 | G20: Cart Corral | H20: Cart Corral | I20: Cart Corral | M20: =L20*$J20 -> 0 | O20: =N20*$J20 -> 0 | Q20: =P20*$J20 -> 0 | S20: =R20*$J20 -> 0 | U20: =T20*$J20 -> 0 | W20: =V20*$J20 -> 0
E21: =SUM(B21:D21) -> 0 | G21: Bollards | M21: =L21*$J21 -> 0 | O21: =N21*$J21 -> 0 | Q21: =P21*$J21 -> 0 | S21: =R21*$J21 -> 0 | U21: =T21*$J21 -> 0 | W21: =V21*$J21 -> 0
E22: =SUM(B22:D22) -> 0 | G22: Bar Steel | M22: =L22*$J22 -> 0 | O22: =N22*$J22 -> 0 | Q22: =P22*$J22 -> 0 | S22: =R22*$J22 -> 0 | U22: =T22*$J22 -> 0 | W22: =V22*$J22 -> 0
E23: =SUM(B23:D23) -> 0 | G23: Pipe protection in garage | H23: Pipe protection in garage | I23: Pipe protection in garage | M23: =L23*$J23 -> 0 | O23: =N23*$J23 -> 0 | Q23: =P23*$J23 -> 0 | S23: =R23*$J23 -> 0 | U23: =T23*$J23 -> 0 | W23: =V23*$J23 -> 0
E24: =SUM(B24:D24) -> 0 | G24: Ships Ladder | H24: Ships Ladder | I24: Ships Ladder | M24: =L24*$J24 -> 0 | O24: =N24*$J24 -> 0 | Q24: =P24*$J24 -> 0 | S24: =R24*$J24 -> 0 | U24: =T24*$J24 -> 0 | W24: =V24*$J24 -> 0
E25: =SUM(B25:D25) -> 0 | G25: Trench drain grate | H25: Trench drain grate | I25: Trench drain grate | M25: =L25*$J25 -> 0 | O25: =N25*$J25 -> 0 | Q25: =P25*$J25 -> 0 | S25: =R25*$J25 -> 0 | U25: =T25*$J25 -> 0 | W25: =V25*$J25 -> 0
E26: =SUM(B26:D26) -> 0 | G26: Stair Gates | H26: Stair Gates | I26: Stair Gates | M26: =L26*$J26 -> 0 | O26: =N26*$J26 -> 0 | Q26: =P26*$J26 -> 0 | S26: =R26*$J26 -> 0 | U26: =T26*$J26 -> 0 | W26: =V26*$J26 -> 0
E27: =SUM(B27:D27) -> 0 | G27: Bent plate at garage | H27: Bent plate at garage | I27: Bent plate at garage | M27: =L27*$J27 -> 0 | O27: =N27*$J27 -> 0 | Q27: =P27*$J27 -> 0 | S27: =R27*$J27 -> 0 | U27: =T27*$J27 -> 0 | W27: =V27*$J27 -> 0
E28: =SUM(B28:D28) -> 0 | G28: Area well grate | H28: Area well grate | I28: Area well grate | M28: =L28*$J28 -> 0 | O28: =N28*$J28 -> 0 | Q28: =P28*$J28 -> 0 | S28: =R28*$J28 -> 0 | U28: =T28*$J28 -> 0 | W28: =V28*$J28 -> 0
E29: =SUM(B29:D29) -> 0 | M29: =L29*$J29 -> 0 | O29: =N29*$J29 -> 0 | Q29: =P29*$J29 -> 0 | S29: =R29*$J29 -> 0 | U29: =T29*$J29 -> 0 | W29: =V29*$J29 -> 0
E30: =SUM(B30:D30) -> 0 | M30: =L30*$J30 -> 0 | O30: =N30*$J30 -> 0 | Q30: =P30*$J30 -> 0 | S30: =R30*$J30 -> 0 | U30: =T30*$J30 -> 0 | W30: =V30*$J30 -> 0
E31: =SUM(B31:D31) -> 0 | M31: =L31*$J31 -> 0 | O31: =N31*$J31 -> 0 | Q31: =P31*$J31 -> 0 | S31: =R31*$J31 -> 0 | U31: =T31*$J31 -> 0 | W31: =V31*$J31 -> 0
E32: =SUM(B32:D32) -> 0 | M32: =L32*$J32 -> 0 | O32: =N32*$J32 -> 0 | Q32: =P32*$J32 -> 0 | S32: =R32*$J32 -> 0 | U32: =T32*$J32 -> 0 | W32: =V32*$J32 -> 0
E33: =SUM(B33:D33) -> 0 | M33: =L33*$J33 -> 0 | O33: =N33*$J33 -> 0 | Q33: =P33*$J33 -> 0 | S33: =R33*$J33 -> 0 | U33: =T33*$J33 -> 0 | W33: =V33*$J33 -> 0
E34: =SUM(B34:D34) -> 0 | M34: =L34*$J34 -> 0 | O34: =N34*$J34 -> 0 | Q34: =P34*$J34 -> 0 | S34: =R34*$J34 -> 0 | U34: =T34*$J34 -> 0 | W34: =V34*$J34 -> 0
B35: =SUM(B13:B34) -> 0 | C35: =SUM(C13:C34) -> 0 | D35: =SUM(D13:D34) -> 0 | E35: =SUM(E9:E34) -> 0 | G35: SUBTOTAL | M35: =SUM(M9:M34) -> 0 | O35: =SUM(O9:O34) -> 0 | Q35: =SUM(Q9:Q34) -> 0 | S35: =SUM(S9:S34) -> 0 | U35: =SUM(U9:U34) -> 0 | W35: =SUM(W9:W34) -> 0
G36: TAX RATE % | M36: =$C$44 -> 0 | O36: =$C$44 -> 0 | Q36: =$C$44 -> 0 | S36: =$C$44 -> 0 | U36: =$C$44 -> 0 | W36: =$C$44 -> 0
G37: TOTAL TAX | M37: =M35*M36 -> 0 | O37: =O35*O36 -> 0 | Q37: =Q35*Q36 -> 0 | S37: =S35*S36 -> 0 | U37: =U35*U36 -> 0 | W37: =W35*W36 -> 0
B38: =B35 -> 0 | C38: =C35 -> 0 | D38: =D35 -> 0 | E38: =SUM(E35) -> 0 | G38: GRAND TOTAL | M38: =SUM(M35,M37) -> 0 | O38: =SUM(O35,O37) -> 0 | Q38: =SUM(Q35,Q37) -> 0 | S38: =SUM(S35,S37) -> 0 | U38: =SUM(U35,U37) -> 0 | W38: =SUM(W35,W37) -> 0
G39: BUDGET - OVER/(UNDER) | M39: =M38-$E$35 -> 0 | O39: =O38-$E$35 -> 0 | Q39: =Q38-$E$35 -> 0 | S39: =S38-$E$35 -> 0 | U39: =U38-$E$35 -> 0 | W39: =W38-$E$35 -> 0
G40: BUDGET - OVER/(UNDER) % | M40: =M39 / $E$38 -> #DIV/0! | O40: =O39 / $E$38 -> #DIV/0! | Q40: =Q39 / $E$38 -> #DIV/0! | S40: =S39 / $E$38 -> #DIV/0! | U40: =U39 / $E$38 -> #DIV/0! | W40: =W39 / $E$38 -> #DIV/0!
...

Sheet 05-7210 Alum Decks
B1: INDEX
B2: TYPE OF WORK: | D2: {=MID(CELL("filename", A1), FIND("]", CELL("filename", A1)) + 1, 255)} -> #VALUE! | J2: VENDOR NUMBER | L2: 1 | N2: 2 | P2: 3 | R2: 4 | T2: 5 | V2: 6
B3: PROJECT NAME: | D3: ='Project Info'!D4 -> NAME | J3: NAME:
B4: PROJECT DATE: | D4: ='Project Info'!D5 -> DATE | J4: CONTACT:
J5: PHONE:
J6: EMAIL:
B7: BUDGET: | J7: DATE:
B8: LABOR | C8: MATERIAL | D8: SUB | E8: TOTAL | F8: COST CODE | G8: ITEM DESCRIPTION | J8: QUANTITY | K8: UNIT | L8: PRICE | M8: TOTAL | N8: PRICE | O8: TOTAL | P8: PRICE | Q8: TOTAL | R8: PRICE | S8: TOTAL | T8: PRICE | U8: TOTAL | V8: PRICE | W8: TOTAL
C9: LOW | D9: {=MIN(IF(M35:W35>0, M35:W35))} -> 0 | E9: =SUM(B9:D9) -> 0 | F9: 05-7210 | G9: Aluminum Decks and Railings | M9: =L9*$J9 -> 0 | O9: =N9*$J9 -> 0 | Q9: =P9*$J9 -> 0 | S9: =R9*$J9 -> 0 | U9: =T9*$J9 -> 0 | W9: =V9*$J9 -> 0
E10: =SUM(B10:D10) -> 0 | M10: =L10*$J10 -> 0 | O10: =N10*$J10 -> 0 | Q10: =P10*$J10 -> 0 | S10: =R10*$J10 -> 0 | U10: =T10*$J10 -> 0 | W10: =V10*$J10 -> 0
E11: =SUM(B11:D11) -> 0 | G11: Aluminum balconies | H11: Aluminum balconies | I11: Aluminum balconies | M11: =L11*$J11 -> 0 | O11: =N11*$J11 -> 0 | Q11: =P11*$J11 -> 0 | S11: =R11*$J11 -> 0 | U11: =T11*$J11 -> 0 | W11: =V11*$J11 -> 0
E12: =SUM(B12:D12) -> 0 | G12: Aluminum railings | H12: Aluminum railings | I12: Aluminum railings | M12: =L12*$J12 -> 0 | O12: =N12*$J12 -> 0 | Q12: =P12*$J12 -> 0 | S12: =R12*$J12 -> 0 | U12: =T12*$J12 -> 0 | W12: =V12*$J12 -> 0
E13: =SUM(B13:D13) -> 0 | G13: Podium level units | H13: Podium level units | I13: Podium level units | M13: =L13*$J13 -> 0 | O13: =N13*$J13 -> 0 | Q13: =P13*$J13 -> 0 | S13: =R13*$J13 -> 0 | U13: =T13*$J13 -> 0 | W13: =V13*$J13 -> 0
E14: =SUM(B14:D14) -> 0 | G14: Amenity deck | H14: Amenity deck | I14: Amenity deck | M14: =L14*$J14 -> 0 | O14: =N14*$J14 -> 0 | Q14: =P14*$J14 -> 0 | S14: =R14*$J14 -> 0 | U14: =T14*$J14 -> 0 | W14: =V14*$J14 -> 0
E15: =SUM(B15:D15) -> 0 | G15: Knife plates and fasteners | H15: Knife plates and fasteners | I15: Knife plates and fasteners | M15: =L15*$J15 -> 0 | O15: =N15*$J15 -> 0 | Q15: =P15*$J15 -> 0 | S15: =R15*$J15 -> 0 | U15: =T15*$J15 -> 0 | W15: =V15*$J15 -> 0
E16: =SUM(B16:D16) -> 0 | G16: Amenity deck parapet | H16: Amenity deck parapet | I16: Amenity deck parapet | M16: =L16*$J16 -> 0 | O16: =N16*$J16 -> 0 | Q16: =P16*$J16 -> 0 | S16: =R16*$J16 -> 0 | U16: =T16*$J16 -> 0 | W16: =V16*$J16 -> 0
E17: =SUM(B17:D17) -> 0 | G17: Sky deck parapets | H17: Sky deck parapets | I17: Sky deck parapets | M17: =L17*$J17 -> 0 | O17: =N17*$J17 -> 0 | Q17: =P17*$J17 -> 0 | S17: =R17*$J17 -> 0 | U17: =T17*$J17 -> 0 | W17: =V17*$J17 -> 0
E18: =SUM(B18:D18) -> 0 | M18: =L18*$J18 -> 0 | O18: =N18*$J18 -> 0 | Q18: =P18*$J18 -> 0 | S18: =R18*$J18 -> 0 | U18: =T18*$J18 -> 0 | W18: =V18*$J18 -> 0
E19: =SUM(B19:D19) -> 0 | M19: =L19*$J19 -> 0 | O19: =N19*$J19 -> 0 | Q19: =P19*$J19 -> 0 | S19: =R19*$J19 -> 0 | U19: =T19*$J19 -> 0 | W19: =V19*$J19 -> 0
E20: =SUM(B20:D20) -> 0 | G20: Pergolas | H20: Pergolas | I20: Pergolas | M20: =L20*$J20 -> 0 | O20: =N20*$J20 -> 0 | Q20: =P20*$J20 -> 0 | S20: =R20*$J20 -> 0 | U20: =T20*$J20 -> 0 | W20: =V20*$J20 -> 0
E21: =SUM(B21:D21) -> 0 | M21: =L21*$J21 -> 0 | O21: =N21*$J21 -> 0 | Q21: =P21*$J21 -> 0 | S21: =R21*$J21 -> 0 | U21: =T21*$J21 -> 0 | W21: =V21*$J21 -> 0
E22: =SUM(B22:D22) -> 0 | M22: =L22*$J22 -> 0 | O22: =N22*$J22 -> 0 | Q22: =P22*$J22 -> 0 | S22: =R22*$J22 -> 0 | U22: =T22*$J22 -> 0 | W22: =V22*$J22 -> 0
E23: =SUM(B23:D23) -> 0 | G23: Design and Engineering | H23: Design and Engineering | I23: Design and Engineering | M23: =L23*$J23 -> 0 | O23: =N23*$J23 -> 0 | Q23: =P23*$J23 -> 0 | S23: =R23*$J23 -> 0 | U23: =T23*$J23 -> 0 | W23: =V23*$J23 -> 0
E24: =SUM(B24:D24) -> 0 | M24: =L24*$J24 -> 0 | O24: =N24*$J24 -> 0 | Q24: =P24*$J24 -> 0 | S24: =R24*$J24 -> 0 | U24: =T24*$J24 -> 0 | W24: =V24*$J24 -> 0
E25: =SUM(B25:D25) -> 0 | M25: =L25*$J25 -> 0 | O25: =N25*$J25 -> 0 | Q25: =P25*$J25 -> 0 | S25: =R25*$J25 -> 0 | U25: =T25*$J25 -> 0 | W25: =V25*$J25 -> 0
E26: =SUM(B26:D26) -> 0 | G26: Installation | H26: Installation | I26: Installation | M26: =L26*$J26 -> 0 | O26: =N26*$J26 -> 0 | Q26: =P26*$J26 -> 0 | S26: =R26*$J26 -> 0 | U26: =T26*$J26 -> 0 | W26: =V26*$J26 -> 0
E27: =SUM(B27:D27) -> 0 | M27: =L27*$J27 -> 0 | O27: =N27*$J27 -> 0 | Q27: =P27*$J27 -> 0 | S27: =R27*$J27 -> 0 | U27: =T27*$J27 -> 0 | W27: =V27*$J27 -> 0
E28: =SUM(B28:D28) -> 0 | M28: =L28*$J28 -> 0 | O28: =N28*$J28 -> 0 | Q28: =P28*$J28 -> 0 | S28: =R28*$J28 -> 0 | U28: =T28*$J28 -> 0 | W28: =V28*$J28 -> 0
E29: =SUM(B29:D29) -> 0 | M29: =L29*$J29 -> 0 | O29: =N29*$J29 -> 0 | Q29: =P29*$J29 -> 0 | S29: =R29*$J29 -> 0 | U29: =T29*$J29 -> 0 | W29: =V29*$J29 -> 0
E30: =SUM(B30:D30) -> 0 | M30: =L30*$J30 -> 0 | O30: =N30*$J30 -> 0 | Q30: =P30*$J30 -> 0 | S30: =R30*$J30 -> 0 | U30: =T30*$J30 -> 0 | W30: =V30*$J30 -> 0
E31: =SUM(B31:D31) -> 0 | M31: =L31*$J31 -> 0 | O31: =N31*$J31 -> 0 | Q31: =P31*$J31 -> 0 | S31: =R31*$J31 -> 0 | U31: =T31*$J31 -> 0 | W31: =V31*$J31 -> 0
B32: =SUM(B9:B31) -> 0 | C32: =SUM(C9:C31) -> 0 | D32: =SUM(D9:D31) -> 0 | E32: =SUM(E9:E31) -> 0 | G32: SUBTOTAL | M32: =SUM(M9:M31) -> 0 | O32: =SUM(O9:O31) -> 0 | Q32: =SUM(Q9:Q31) -> 0 | S32: =SUM(S9:S31) -> 0 | U32: =SUM(U9:U31) -> 0 | W32: =SUM(W9:W31) -> 0
G33: TAX RATE % | M33: =$C$41 -> 0 | O33: =$C$41 -> 0 | Q33: =$C$41 -> 0 | S33: =$C$41 -> 0 | U33: =$C$41 -> 0 | W33: =$C$41 -> 0
G34: TOTAL TAX | M34: =M32*M33 -> 0 | O34: =O32*O33 -> 0 | Q34: =Q32*Q33 -> 0 | S34: =S32*S33 -> 0 | U34: =U32*U33 -> 0 | W34: =W32*W33 -> 0
B35: =B32 -> 0 | C35: =C32 -> 0 | D35: =D32 -> 0 | E35: =SUM(E32) -> 0 | G35: GRAND TOTAL | M35: =SUM(M32,M34) -> 0 | O35: =SUM(O32,O34) -> 0 | Q35: =SUM(Q32,Q34) -> 0 | S35: =SUM(S32,S34) -> 0 | U35: =SUM(U32,U34) -> 0 | W35: =SUM(W32,W34) -> 0
G36: BUDGET - OVER/(UNDER) | M36: =M35-$E$35 -> 0 | O36: =O35-$E$35 -> 0 | Q36: =Q35-$E$35 -> 0 | S36: =S35-$E$35 -> 0 | U36: =U35-$E$35 -> 0 | W36: =W35-$E$35 -> 0
G37: BUDGET - OVER/(UNDER) % | M37: =M36 / $E$35 -> #DIV/0! | O37: =O36 / $E$35 -> #DIV/0! | Q37: =Q36 / $E$35 -> #DIV/0! | S37: =S36 / $E$35 -> #DIV/0! | U37: =U36 / $E$35 -> #DIV/0! | W37: =W36 / $E$35 -> #DIV/0!
B41: TAX RATE | C41: 0

Sheet 06-1000 Rough Carp
B1: INDEX
B2: TYPE OF WORK: | D2: {=MID(CELL("filename", A1), FIND("]", CELL("filename", A1)) + 1, 255)} -> #VALUE! | J2: VENDOR NUMBER | L2: 1 | N2: 2 | P2: 3 | R2: 4 | T2: 5 | V2: 6
B3: PROJECT NAME: | D3: ='Project Info'!D4 -> NAME | J3: NAME:
B4: PROJECT DATE: | D4: ='Project Info'!D5 -> DATE | J4: CONTACT:
J5: PHONE:
J6: EMAIL:
B7: BUDGET: | J7: DATE:
B8: LABOR | C8: MATERIAL | D8: SUB | E8: TOTAL | F8: COST CODE | G8: ITEM DESCRIPTION | J8: QUANTITY | K8: UNIT | L8: PRICE | M8: TOTAL | N8: PRICE | O8: TOTAL | P8: PRICE | Q8: TOTAL | R8: PRICE | S8: TOTAL | T8: PRICE | U8: TOTAL | V8: PRICE | W8: TOTAL
